Internal Server Error: /accounts/login/
Traceback (most recent call last):
  File "C:\Users\cris_\OneDrive\Escritorio\sistema_hotel\venv\Lib\site-packages\django\core\handlers\exception.py", line 55, in inner
    response = get_response(request)
  File "C:\Users\cris_\OneDrive\Escritorio\sistema_hotel\venv\Lib\site-packages\django\core\handlers\base.py", line 220, in _get_response
    response = response.render()
  File "C:\Users\cris_\OneDrive\Escritorio\sistema_hotel\venv\Lib\site-packages\django\template\response.py", line 114, in render
    self.content = self.rendered_content
                   ^^^^^^^^^^^^^^^^^^^^^
  File "C:\Users\cris_\OneDrive\Escritorio\sistema_hotel\venv\Lib\site-packages\django\template\response.py", line 92, in rendered_content
    return template.render(context, self._request)
           ~~~~~~~~~~~~~~~^^^^^^^^^^^^^^^^^^^^^^^^
  File "C:\Users\cris_\OneDrive\Escritorio\sistema_hotel\venv\Lib\site-packages\django\template\backends\django.py", line 61, in render
    return self.template.render(context)
           ~~~~~~~~~~~~~~~~~~~~^^^^^^^^^
  File "C:\Users\cris_\OneDrive\Escritorio\sistema_hotel\venv\Lib\site-packages\django\template\base.py", line 171, in render
    return self._render(context)
           ~~~~~~~~~~~~^^^^^^^^^
  File "C:\Users\cris_\OneDrive\Escritorio\sistema_hotel\venv\Lib\site-packages\django\template\base.py", line 163, in _render
    return self.nodelist.render(context)
           ~~~~~~~~~~~~~~~~~~~~^^^^^^^^^
  File "C:\Users\cris_\OneDrive\Escritorio\sistema_hotel\venv\Lib\site-packages\django\template\base.py", line 1000, in render
    return SafeString("".join([node.render_annotated(context) for node in self]))
                               ~~~~~~~~~~~~~~~~~~~~~^^^^^^^^^
  File "C:\Users\cris_\OneDrive\Escritorio\sistema_hotel\venv\Lib\site-packages\django\template\base.py", line 961, in render_annotated
    return self.render(context)
           ~~~~~~~~~~~^^^^^^^^^
  File "C:\Users\cris_\OneDrive\Escritorio\sistema_hotel\venv\Lib\site-packages\django\template\loader_tags.py", line 159, in render
    return compiled_parent._render(context)
           ~~~~~~~~~~~~~~~~~~~~~~~^^^^^^^^^
  File "C:\Users\cris_\OneDrive\Escritorio\sistema_hotel\venv\Lib\site-packages\django\template\base.py", line 163, in _render
    return self.nodelist.render(context)
           ~~~~~~~~~~~~~~~~~~~~^^^^^^^^^
  File "C:\Users\cris_\OneDrive\Escritorio\sistema_hotel\venv\Lib\site-packages\django\template\base.py", line 1000, in render
    return SafeString("".join([node.render_annotated(context) for node in self]))
                               ~~~~~~~~~~~~~~~~~~~~~^^^^^^^^^
  File "C:\Users\cris_\OneDrive\Escritorio\sistema_hotel\venv\Lib\site-packages\django\template\base.py", line 961, in render_annotated
    return self.render(context)
           ~~~~~~~~~~~^^^^^^^^^
  File "C:\Users\cris_\OneDrive\Escritorio\sistema_hotel\venv\Lib\site-packages\django\templatetags\static.py", line 116, in render
    url = self.url(context)
  File "C:\Users\cris_\OneDrive\Escritorio\sistema_hotel\venv\Lib\site-packages\django\templatetags\static.py", line 113, in url
    return self.handle_simple(path)
           ~~~~~~~~~~~~~~~~~~^^^^^^
  File "C:\Users\cris_\OneDrive\Escritorio\sistema_hotel\venv\Lib\site-packages\django\templatetags\static.py", line 129, in handle_simple
    return staticfiles_storage.url(path)
           ~~~~~~~~~~~~~~~~~~~~~~~^^^^^^
  File "C:\Users\cris_\OneDrive\Escritorio\sistema_hotel\venv\Lib\site-packages\django\contrib\staticfiles\storage.py", line 203, in url
    return self._url(self.stored_name, name, force)
           ~~~~~~~~~^^^^^^^^^^^^^^^^^^^^^^^^^^^^^^^
  File "C:\Users\cris_\OneDrive\Escritorio\sistema_hotel\venv\Lib\site-packages\django\contrib\staticfiles\storage.py", line 182, in _url
    hashed_name = hashed_name_func(*args)
  File "C:\Users\cris_\OneDrive\Escritorio\sistema_hotel\venv\Lib\site-packages\django\contrib\staticfiles\storage.py", line 516, in stored_name
    raise ValueError(
        "Missing staticfiles manifest entry for '%s'" % clean_name
    )
ValueError: Missing staticfiles manifest entry for 'css/style.css'
"GET /accounts/login/ HTTP/1.1" 500 145
Internal Server Error: /accounts/login/
Traceback (most recent call last):
  File "C:\Users\cris_\OneDrive\Escritorio\sistema_hotel\venv\Lib\site-packages\django\core\handlers\exception.py", line 55, in inner
    response = get_response(request)
  File "C:\Users\cris_\OneDrive\Escritorio\sistema_hotel\venv\Lib\site-packages\django\core\handlers\base.py", line 220, in _get_response
    response = response.render()
  File "C:\Users\cris_\OneDrive\Escritorio\sistema_hotel\venv\Lib\site-packages\django\template\response.py", line 114, in render
    self.content = self.rendered_content
                   ^^^^^^^^^^^^^^^^^^^^^
  File "C:\Users\cris_\OneDrive\Escritorio\sistema_hotel\venv\Lib\site-packages\django\template\response.py", line 92, in rendered_content
    return template.render(context, self._request)
           ~~~~~~~~~~~~~~~^^^^^^^^^^^^^^^^^^^^^^^^
  File "C:\Users\cris_\OneDrive\Escritorio\sistema_hotel\venv\Lib\site-packages\django\template\backends\django.py", line 61, in render
    return self.template.render(context)
           ~~~~~~~~~~~~~~~~~~~~^^^^^^^^^
  File "C:\Users\cris_\OneDrive\Escritorio\sistema_hotel\venv\Lib\site-packages\django\template\base.py", line 171, in render
    return self._render(context)
           ~~~~~~~~~~~~^^^^^^^^^
  File "C:\Users\cris_\OneDrive\Escritorio\sistema_hotel\venv\Lib\site-packages\django\template\base.py", line 163, in _render
    return self.nodelist.render(context)
           ~~~~~~~~~~~~~~~~~~~~^^^^^^^^^
  File "C:\Users\cris_\OneDrive\Escritorio\sistema_hotel\venv\Lib\site-packages\django\template\base.py", line 1000, in render
    return SafeString("".join([node.render_annotated(context) for node in self]))
                               ~~~~~~~~~~~~~~~~~~~~~^^^^^^^^^
  File "C:\Users\cris_\OneDrive\Escritorio\sistema_hotel\venv\Lib\site-packages\django\template\base.py", line 961, in render_annotated
    return self.render(context)
           ~~~~~~~~~~~^^^^^^^^^
  File "C:\Users\cris_\OneDrive\Escritorio\sistema_hotel\venv\Lib\site-packages\django\template\loader_tags.py", line 159, in render
    return compiled_parent._render(context)
           ~~~~~~~~~~~~~~~~~~~~~~~^^^^^^^^^
  File "C:\Users\cris_\OneDrive\Escritorio\sistema_hotel\venv\Lib\site-packages\django\template\base.py", line 163, in _render
    return self.nodelist.render(context)
           ~~~~~~~~~~~~~~~~~~~~^^^^^^^^^
  File "C:\Users\cris_\OneDrive\Escritorio\sistema_hotel\venv\Lib\site-packages\django\template\base.py", line 1000, in render
    return SafeString("".join([node.render_annotated(context) for node in self]))
                               ~~~~~~~~~~~~~~~~~~~~~^^^^^^^^^
  File "C:\Users\cris_\OneDrive\Escritorio\sistema_hotel\venv\Lib\site-packages\django\template\base.py", line 961, in render_annotated
    return self.render(context)
           ~~~~~~~~~~~^^^^^^^^^
  File "C:\Users\cris_\OneDrive\Escritorio\sistema_hotel\venv\Lib\site-packages\django\templatetags\static.py", line 116, in render
    url = self.url(context)
  File "C:\Users\cris_\OneDrive\Escritorio\sistema_hotel\venv\Lib\site-packages\django\templatetags\static.py", line 113, in url
    return self.handle_simple(path)
           ~~~~~~~~~~~~~~~~~~^^^^^^
  File "C:\Users\cris_\OneDrive\Escritorio\sistema_hotel\venv\Lib\site-packages\django\templatetags\static.py", line 129, in handle_simple
    return staticfiles_storage.url(path)
           ~~~~~~~~~~~~~~~~~~~~~~~^^^^^^
  File "C:\Users\cris_\OneDrive\Escritorio\sistema_hotel\venv\Lib\site-packages\django\contrib\staticfiles\storage.py", line 203, in url
    return self._url(self.stored_name, name, force)
           ~~~~~~~~~^^^^^^^^^^^^^^^^^^^^^^^^^^^^^^^
  File "C:\Users\cris_\OneDrive\Escritorio\sistema_hotel\venv\Lib\site-packages\django\contrib\staticfiles\storage.py", line 182, in _url
    hashed_name = hashed_name_func(*args)
  File "C:\Users\cris_\OneDrive\Escritorio\sistema_hotel\venv\Lib\site-packages\django\contrib\staticfiles\storage.py", line 516, in stored_name
    raise ValueError(
        "Missing staticfiles manifest entry for '%s'" % clean_name
    )
ValueError: Missing staticfiles manifest entry for 'css/style.css'
"GET /accounts/login/ HTTP/1.1" 500 145
Internal Server Error: /login/
Traceback (most recent call last):
  File "/usr/local/lib/python3.13/site-packages/django/db/backends/base/base.py", line 275, in ensure_connection
    self.connect()
    ~~~~~~~~~~~~^^
  File "/usr/local/lib/python3.13/site-packages/django/utils/asyncio.py", line 26, in inner
    return func(*args, **kwargs)
  File "/usr/local/lib/python3.13/site-packages/django/db/backends/base/base.py", line 256, in connect
    self.connection = self.get_new_connection(conn_params)
                      ~~~~~~~~~~~~~~~~~~~~~~~^^^^^^^^^^^^^
  File "/usr/local/lib/python3.13/site-packages/django/utils/asyncio.py", line 26, in inner
    return func(*args, **kwargs)
  File "/usr/local/lib/python3.13/site-packages/django/db/backends/postgresql/base.py", line 277, in get_new_connection
    connection = self.Database.connect(**conn_params)
  File "/usr/local/lib/python3.13/site-packages/psycopg2/__init__.py", line 122, in connect
    conn = _connect(dsn, connection_factory=connection_factory, **kwasync)
psycopg2.OperationalError: connection to server at "aws-0-us-west-1.pooler.supabase.com" (54.177.55.191), port 5432 failed: FATAL:  Tenant or user not found
connection to server at "aws-0-us-west-1.pooler.supabase.com" (54.177.55.191), port 5432 failed: FATAL:  Tenant or user not found


The above exception was the direct cause of the following exception:

Traceback (most recent call last):
  File "/usr/local/lib/python3.13/site-packages/django/core/handlers/exception.py", line 55, in inner
    response = get_response(request)
  File "/usr/local/lib/python3.13/site-packages/django/core/handlers/base.py", line 197, in _get_response
    response = wrapped_callback(request, *callback_args, **callback_kwargs)
  File "/usr/local/lib/python3.13/site-packages/django/views/generic/base.py", line 104, in view
    return self.dispatch(request, *args, **kwargs)
           ~~~~~~~~~~~~~^^^^^^^^^^^^^^^^^^^^^^^^^^
  File "/usr/local/lib/python3.13/site-packages/django/utils/decorators.py", line 48, in _wrapper
    return bound_method(*args, **kwargs)
  File "/usr/local/lib/python3.13/site-packages/django/views/decorators/debug.py", line 143, in sensitive_post_parameters_wrapper
    return view(request, *args, **kwargs)
  File "/usr/local/lib/python3.13/site-packages/django/utils/decorators.py", line 48, in _wrapper
    return bound_method(*args, **kwargs)
  File "/usr/local/lib/python3.13/site-packages/django/utils/decorators.py", line 188, in _view_wrapper
    result = _process_exception(request, e)
  File "/usr/local/lib/python3.13/site-packages/django/utils/decorators.py", line 186, in _view_wrapper
    response = view_func(request, *args, **kwargs)
  File "/usr/local/lib/python3.13/site-packages/django/utils/decorators.py", line 48, in _wrapper
    return bound_method(*args, **kwargs)
  File "/usr/local/lib/python3.13/site-packages/django/views/decorators/cache.py", line 80, in _view_wrapper
    response = view_func(request, *args, **kwargs)
  File "/usr/local/lib/python3.13/site-packages/django/contrib/auth/views.py", line 88, in dispatch
    return super().dispatch(request, *args, **kwargs)
           ~~~~~~~~~~~~~~~~^^^^^^^^^^^^^^^^^^^^^^^^^^
  File "/usr/local/lib/python3.13/site-packages/django/views/generic/base.py", line 143, in dispatch
    return handler(request, *args, **kwargs)
  File "/usr/local/lib/python3.13/site-packages/django/views/generic/edit.py", line 150, in post
    if form.is_valid():
       ~~~~~~~~~~~~~^^
  File "/usr/local/lib/python3.13/site-packages/django/forms/forms.py", line 197, in is_valid
    return self.is_bound and not self.errors
                                 ^^^^^^^^^^^
  File "/usr/local/lib/python3.13/site-packages/django/forms/forms.py", line 192, in errors
    self.full_clean()
    ~~~~~~~~~~~~~~~^^
  File "/usr/local/lib/python3.13/site-packages/django/forms/forms.py", line 328, in full_clean
    self._clean_form()
    ~~~~~~~~~~~~~~~~^^
  File "/usr/local/lib/python3.13/site-packages/django/forms/forms.py", line 349, in _clean_form
    cleaned_data = self.clean()
  File "/usr/local/lib/python3.13/site-packages/django/contrib/auth/forms.py", line 250, in clean
    self.user_cache = authenticate(
                      ~~~~~~~~~~~~^
        self.request, username=username, password=password
        ^^^^^^^^^^^^^^^^^^^^^^^^^^^^^^^^^^^^^^^^^^^^^^^^^^
    )
    ^
  File "/usr/local/lib/python3.13/site-packages/django/views/decorators/debug.py", line 75, in sensitive_variables_wrapper
    return func(*func_args, **func_kwargs)
  File "/usr/local/lib/python3.13/site-packages/django/contrib/auth/__init__.py", line 79, in authenticate
    user = backend.authenticate(request, **credentials)
  File "/usr/local/lib/python3.13/site-packages/django/contrib/auth/backends.py", line 42, in authenticate
    user = UserModel._default_manager.get_by_natural_key(username)
  File "/usr/local/lib/python3.13/site-packages/django/contrib/auth/base_user.py", line 56, in get_by_natural_key
    return self.get(**{self.model.USERNAME_FIELD: username})
           ~~~~~~~~^^^^^^^^^^^^^^^^^^^^^^^^^^^^^^^^^^^^^^^^^
  File "/usr/local/lib/python3.13/site-packages/django/db/models/manager.py", line 87, in manager_method
    return getattr(self.get_queryset(), name)(*args, **kwargs)
           ~~~~~~~~~~~~~~~~~~~~~~~~~~~~~~~~~~^^^^^^^^^^^^^^^^^
  File "/usr/local/lib/python3.13/site-packages/django/db/models/query.py", line 645, in get
    num = len(clone)
  File "/usr/local/lib/python3.13/site-packages/django/db/models/query.py", line 382, in __len__
    self._fetch_all()
    ~~~~~~~~~~~~~~~^^
  File "/usr/local/lib/python3.13/site-packages/django/db/models/query.py", line 1928, in _fetch_all
    self._result_cache = list(self._iterable_class(self))
                         ~~~~^^^^^^^^^^^^^^^^^^^^^^^^^^^^
  File "/usr/local/lib/python3.13/site-packages/django/db/models/query.py", line 91, in __iter__
    results = compiler.execute_sql(
        chunked_fetch=self.chunked_fetch, chunk_size=self.chunk_size
    )
  File "/usr/local/lib/python3.13/site-packages/django/db/models/sql/compiler.py", line 1560, in execute_sql
    cursor = self.connection.cursor()
  File "/usr/local/lib/python3.13/site-packages/django/utils/asyncio.py", line 26, in inner
    return func(*args, **kwargs)
  File "/usr/local/lib/python3.13/site-packages/django/db/backends/base/base.py", line 316, in cursor
    return self._cursor()
           ~~~~~~~~~~~~^^
  File "/usr/local/lib/python3.13/site-packages/django/db/backends/base/base.py", line 292, in _cursor
    self.ensure_connection()
    ~~~~~~~~~~~~~~~~~~~~~~^^
  File "/usr/local/lib/python3.13/site-packages/django/utils/asyncio.py", line 26, in inner
    return func(*args, **kwargs)
  File "/usr/local/lib/python3.13/site-packages/django/db/backends/base/base.py", line 274, in ensure_connection
    with self.wrap_database_errors:
         ^^^^^^^^^^^^^^^^^^^^^^^^^
  File "/usr/local/lib/python3.13/site-packages/django/db/utils.py", line 91, in __exit__
    raise dj_exc_value.with_traceback(traceback) from exc_value
  File "/usr/local/lib/python3.13/site-packages/django/db/backends/base/base.py", line 275, in ensure_connection
    self.connect()
    ~~~~~~~~~~~~^^
  File "/usr/local/lib/python3.13/site-packages/django/utils/asyncio.py", line 26, in inner
    return func(*args, **kwargs)
  File "/usr/local/lib/python3.13/site-packages/django/db/backends/base/base.py", line 256, in connect
    self.connection = self.get_new_connection(conn_params)
                      ~~~~~~~~~~~~~~~~~~~~~~~^^^^^^^^^^^^^
  File "/usr/local/lib/python3.13/site-packages/django/utils/asyncio.py", line 26, in inner
    return func(*args, **kwargs)
  File "/usr/local/lib/python3.13/site-packages/django/db/backends/postgresql/base.py", line 277, in get_new_connection
    connection = self.Database.connect(**conn_params)
  File "/usr/local/lib/python3.13/site-packages/psycopg2/__init__.py", line 122, in connect
    conn = _connect(dsn, connection_factory=connection_factory, **kwasync)
django.db.utils.OperationalError: connection to server at "aws-0-us-west-1.pooler.supabase.com" (54.177.55.191), port 5432 failed: FATAL:  Tenant or user not found
connection to server at "aws-0-us-west-1.pooler.supabase.com" (54.177.55.191), port 5432 failed: FATAL:  Tenant or user not found

Internal Server Error: /reservas/planing/
Traceback (most recent call last):
  File "/usr/local/lib/python3.13/site-packages/django/db/backends/base/base.py", line 275, in ensure_connection
    self.connect()
    ~~~~~~~~~~~~^^
  File "/usr/local/lib/python3.13/site-packages/django/utils/asyncio.py", line 26, in inner
    return func(*args, **kwargs)
  File "/usr/local/lib/python3.13/site-packages/django/db/backends/base/base.py", line 256, in connect
    self.connection = self.get_new_connection(conn_params)
                      ~~~~~~~~~~~~~~~~~~~~~~~^^^^^^^^^^^^^
  File "/usr/local/lib/python3.13/site-packages/django/utils/asyncio.py", line 26, in inner
    return func(*args, **kwargs)
  File "/usr/local/lib/python3.13/site-packages/django/db/backends/postgresql/base.py", line 277, in get_new_connection
    connection = self.Database.connect(**conn_params)
  File "/usr/local/lib/python3.13/site-packages/psycopg2/__init__.py", line 122, in connect
    conn = _connect(dsn, connection_factory=connection_factory, **kwasync)
psycopg2.OperationalError: connection to server at "aws-0-us-west-1.pooler.supabase.com" (54.177.55.191), port 5432 failed: FATAL:  Tenant or user not found
connection to server at "aws-0-us-west-1.pooler.supabase.com" (54.177.55.191), port 5432 failed: FATAL:  Tenant or user not found


The above exception was the direct cause of the following exception:

Traceback (most recent call last):
  File "/usr/local/lib/python3.13/site-packages/django/core/handlers/exception.py", line 55, in inner
    response = get_response(request)
  File "/usr/local/lib/python3.13/site-packages/django/core/handlers/base.py", line 197, in _get_response
    response = wrapped_callback(request, *callback_args, **callback_kwargs)
  File "/app/reservas/views.py", line 119, in generar_planing
    habitaciones = list(Habitacion.objects.all())
  File "/usr/local/lib/python3.13/site-packages/django/db/models/query.py", line 400, in __iter__
    self._fetch_all()
    ~~~~~~~~~~~~~~~^^
  File "/usr/local/lib/python3.13/site-packages/django/db/models/query.py", line 1928, in _fetch_all
    self._result_cache = list(self._iterable_class(self))
                         ~~~~^^^^^^^^^^^^^^^^^^^^^^^^^^^^
  File "/usr/local/lib/python3.13/site-packages/django/db/models/query.py", line 91, in __iter__
    results = compiler.execute_sql(
        chunked_fetch=self.chunked_fetch, chunk_size=self.chunk_size
    )
  File "/usr/local/lib/python3.13/site-packages/django/db/models/sql/compiler.py", line 1560, in execute_sql
    cursor = self.connection.cursor()
  File "/usr/local/lib/python3.13/site-packages/django/utils/asyncio.py", line 26, in inner
    return func(*args, **kwargs)
  File "/usr/local/lib/python3.13/site-packages/django/db/backends/base/base.py", line 316, in cursor
    return self._cursor()
           ~~~~~~~~~~~~^^
  File "/usr/local/lib/python3.13/site-packages/django/db/backends/base/base.py", line 292, in _cursor
    self.ensure_connection()
    ~~~~~~~~~~~~~~~~~~~~~~^^
  File "/usr/local/lib/python3.13/site-packages/django/utils/asyncio.py", line 26, in inner
    return func(*args, **kwargs)
  File "/usr/local/lib/python3.13/site-packages/django/db/backends/base/base.py", line 274, in ensure_connection
    with self.wrap_database_errors:
         ^^^^^^^^^^^^^^^^^^^^^^^^^
  File "/usr/local/lib/python3.13/site-packages/django/db/utils.py", line 91, in __exit__
    raise dj_exc_value.with_traceback(traceback) from exc_value
  File "/usr/local/lib/python3.13/site-packages/django/db/backends/base/base.py", line 275, in ensure_connection
    self.connect()
    ~~~~~~~~~~~~^^
  File "/usr/local/lib/python3.13/site-packages/django/utils/asyncio.py", line 26, in inner
    return func(*args, **kwargs)
  File "/usr/local/lib/python3.13/site-packages/django/db/backends/base/base.py", line 256, in connect
    self.connection = self.get_new_connection(conn_params)
                      ~~~~~~~~~~~~~~~~~~~~~~~^^^^^^^^^^^^^
  File "/usr/local/lib/python3.13/site-packages/django/utils/asyncio.py", line 26, in inner
    return func(*args, **kwargs)
  File "/usr/local/lib/python3.13/site-packages/django/db/backends/postgresql/base.py", line 277, in get_new_connection
    connection = self.Database.connect(**conn_params)
  File "/usr/local/lib/python3.13/site-packages/psycopg2/__init__.py", line 122, in connect
    conn = _connect(dsn, connection_factory=connection_factory, **kwasync)
django.db.utils.OperationalError: connection to server at "aws-0-us-west-1.pooler.supabase.com" (54.177.55.191), port 5432 failed: FATAL:  Tenant or user not found
connection to server at "aws-0-us-west-1.pooler.supabase.com" (54.177.55.191), port 5432 failed: FATAL:  Tenant or user not found

Internal Server Error: /reservas/listar_reservas/
Traceback (most recent call last):
  File "/usr/local/lib/python3.13/site-packages/django/db/backends/base/base.py", line 275, in ensure_connection
    self.connect()
    ~~~~~~~~~~~~^^
  File "/usr/local/lib/python3.13/site-packages/django/utils/asyncio.py", line 26, in inner
    return func(*args, **kwargs)
  File "/usr/local/lib/python3.13/site-packages/django/db/backends/base/base.py", line 256, in connect
    self.connection = self.get_new_connection(conn_params)
                      ~~~~~~~~~~~~~~~~~~~~~~~^^^^^^^^^^^^^
  File "/usr/local/lib/python3.13/site-packages/django/utils/asyncio.py", line 26, in inner
    return func(*args, **kwargs)
  File "/usr/local/lib/python3.13/site-packages/django/db/backends/postgresql/base.py", line 277, in get_new_connection
    connection = self.Database.connect(**conn_params)
  File "/usr/local/lib/python3.13/site-packages/psycopg2/__init__.py", line 122, in connect
    conn = _connect(dsn, connection_factory=connection_factory, **kwasync)
psycopg2.OperationalError: connection to server at "aws-0-us-west-1.pooler.supabase.com" (54.177.55.191), port 5432 failed: FATAL:  Tenant or user not found
connection to server at "aws-0-us-west-1.pooler.supabase.com" (54.177.55.191), port 5432 failed: FATAL:  Tenant or user not found


The above exception was the direct cause of the following exception:

Traceback (most recent call last):
  File "/usr/local/lib/python3.13/site-packages/django/core/handlers/exception.py", line 55, in inner
    response = get_response(request)
  File "/usr/local/lib/python3.13/site-packages/django/core/handlers/base.py", line 197, in _get_response
    response = wrapped_callback(request, *callback_args, **callback_kwargs)
  File "/app/reservas/views.py", line 465, in listar_reservas
    for reserva in reservas:
                   ^^^^^^^^
  File "/usr/local/lib/python3.13/site-packages/django/db/models/query.py", line 400, in __iter__
    self._fetch_all()
    ~~~~~~~~~~~~~~~^^
  File "/usr/local/lib/python3.13/site-packages/django/db/models/query.py", line 1928, in _fetch_all
    self._result_cache = list(self._iterable_class(self))
                         ~~~~^^^^^^^^^^^^^^^^^^^^^^^^^^^^
  File "/usr/local/lib/python3.13/site-packages/django/db/models/query.py", line 91, in __iter__
    results = compiler.execute_sql(
        chunked_fetch=self.chunked_fetch, chunk_size=self.chunk_size
    )
  File "/usr/local/lib/python3.13/site-packages/django/db/models/sql/compiler.py", line 1560, in execute_sql
    cursor = self.connection.cursor()
  File "/usr/local/lib/python3.13/site-packages/django/utils/asyncio.py", line 26, in inner
    return func(*args, **kwargs)
  File "/usr/local/lib/python3.13/site-packages/django/db/backends/base/base.py", line 316, in cursor
    return self._cursor()
           ~~~~~~~~~~~~^^
  File "/usr/local/lib/python3.13/site-packages/django/db/backends/base/base.py", line 292, in _cursor
    self.ensure_connection()
    ~~~~~~~~~~~~~~~~~~~~~~^^
  File "/usr/local/lib/python3.13/site-packages/django/utils/asyncio.py", line 26, in inner
    return func(*args, **kwargs)
  File "/usr/local/lib/python3.13/site-packages/django/db/backends/base/base.py", line 274, in ensure_connection
    with self.wrap_database_errors:
         ^^^^^^^^^^^^^^^^^^^^^^^^^
  File "/usr/local/lib/python3.13/site-packages/django/db/utils.py", line 91, in __exit__
    raise dj_exc_value.with_traceback(traceback) from exc_value
  File "/usr/local/lib/python3.13/site-packages/django/db/backends/base/base.py", line 275, in ensure_connection
    self.connect()
    ~~~~~~~~~~~~^^
  File "/usr/local/lib/python3.13/site-packages/django/utils/asyncio.py", line 26, in inner
    return func(*args, **kwargs)
  File "/usr/local/lib/python3.13/site-packages/django/db/backends/base/base.py", line 256, in connect
    self.connection = self.get_new_connection(conn_params)
                      ~~~~~~~~~~~~~~~~~~~~~~~^^^^^^^^^^^^^
  File "/usr/local/lib/python3.13/site-packages/django/utils/asyncio.py", line 26, in inner
    return func(*args, **kwargs)
  File "/usr/local/lib/python3.13/site-packages/django/db/backends/postgresql/base.py", line 277, in get_new_connection
    connection = self.Database.connect(**conn_params)
  File "/usr/local/lib/python3.13/site-packages/psycopg2/__init__.py", line 122, in connect
    conn = _connect(dsn, connection_factory=connection_factory, **kwasync)
django.db.utils.OperationalError: connection to server at "aws-0-us-west-1.pooler.supabase.com" (54.177.55.191), port 5432 failed: FATAL:  Tenant or user not found
connection to server at "aws-0-us-west-1.pooler.supabase.com" (54.177.55.191), port 5432 failed: FATAL:  Tenant or user not found

Internal Server Error: /reservas/listar_habitaciones/
Traceback (most recent call last):
  File "/usr/local/lib/python3.13/site-packages/django/db/backends/base/base.py", line 275, in ensure_connection
    self.connect()
    ~~~~~~~~~~~~^^
  File "/usr/local/lib/python3.13/site-packages/django/utils/asyncio.py", line 26, in inner
    return func(*args, **kwargs)
  File "/usr/local/lib/python3.13/site-packages/django/db/backends/base/base.py", line 256, in connect
    self.connection = self.get_new_connection(conn_params)
                      ~~~~~~~~~~~~~~~~~~~~~~~^^^^^^^^^^^^^
  File "/usr/local/lib/python3.13/site-packages/django/utils/asyncio.py", line 26, in inner
    return func(*args, **kwargs)
  File "/usr/local/lib/python3.13/site-packages/django/db/backends/postgresql/base.py", line 277, in get_new_connection
    connection = self.Database.connect(**conn_params)
  File "/usr/local/lib/python3.13/site-packages/psycopg2/__init__.py", line 122, in connect
    conn = _connect(dsn, connection_factory=connection_factory, **kwasync)
psycopg2.OperationalError: connection to server at "aws-0-us-west-1.pooler.supabase.com" (54.177.55.191), port 5432 failed: FATAL:  Tenant or user not found
connection to server at "aws-0-us-west-1.pooler.supabase.com" (54.177.55.191), port 5432 failed: FATAL:  Tenant or user not found


The above exception was the direct cause of the following exception:

Traceback (most recent call last):
  File "/usr/local/lib/python3.13/site-packages/django/core/handlers/exception.py", line 55, in inner
    response = get_response(request)
  File "/usr/local/lib/python3.13/site-packages/django/core/handlers/base.py", line 197, in _get_response
    response = wrapped_callback(request, *callback_args, **callback_kwargs)
  File "/app/reservas/views.py", line 195, in listar_habitaciones
    return render(
        request, "reservas/listar_habitaciones.html", {"habitaciones": habitaciones}
    )
  File "/usr/local/lib/python3.13/site-packages/django/shortcuts.py", line 25, in render
    content = loader.render_to_string(template_name, context, request, using=using)
  File "/usr/local/lib/python3.13/site-packages/django/template/loader.py", line 62, in render_to_string
    return template.render(context, request)
           ~~~~~~~~~~~~~~~^^^^^^^^^^^^^^^^^^
  File "/usr/local/lib/python3.13/site-packages/django/template/backends/django.py", line 61, in render
    return self.template.render(context)
           ~~~~~~~~~~~~~~~~~~~~^^^^^^^^^
  File "/usr/local/lib/python3.13/site-packages/django/template/base.py", line 171, in render
    return self._render(context)
           ~~~~~~~~~~~~^^^^^^^^^
  File "/usr/local/lib/python3.13/site-packages/django/template/base.py", line 163, in _render
    return self.nodelist.render(context)
           ~~~~~~~~~~~~~~~~~~~~^^^^^^^^^
  File "/usr/local/lib/python3.13/site-packages/django/template/base.py", line 1000, in render
    return SafeString("".join([node.render_annotated(context) for node in self]))
                               ~~~~~~~~~~~~~~~~~~~~~^^^^^^^^^
  File "/usr/local/lib/python3.13/site-packages/django/template/base.py", line 961, in render_annotated
    return self.render(context)
           ~~~~~~~~~~~^^^^^^^^^
  File "/usr/local/lib/python3.13/site-packages/django/template/loader_tags.py", line 159, in render
    return compiled_parent._render(context)
           ~~~~~~~~~~~~~~~~~~~~~~~^^^^^^^^^
  File "/usr/local/lib/python3.13/site-packages/django/template/base.py", line 163, in _render
    return self.nodelist.render(context)
           ~~~~~~~~~~~~~~~~~~~~^^^^^^^^^
  File "/usr/local/lib/python3.13/site-packages/django/template/base.py", line 1000, in render
    return SafeString("".join([node.render_annotated(context) for node in self]))
                               ~~~~~~~~~~~~~~~~~~~~~^^^^^^^^^
  File "/usr/local/lib/python3.13/site-packages/django/template/base.py", line 961, in render_annotated
    return self.render(context)
           ~~~~~~~~~~~^^^^^^^^^
  File "/usr/local/lib/python3.13/site-packages/django/template/loader_tags.py", line 65, in render
    result = block.nodelist.render(context)
  File "/usr/local/lib/python3.13/site-packages/django/template/base.py", line 1000, in render
    return SafeString("".join([node.render_annotated(context) for node in self]))
                               ~~~~~~~~~~~~~~~~~~~~~^^^^^^^^^
  File "/usr/local/lib/python3.13/site-packages/django/template/base.py", line 961, in render_annotated
    return self.render(context)
           ~~~~~~~~~~~^^^^^^^^^
  File "/usr/local/lib/python3.13/site-packages/django/template/defaulttags.py", line 198, in render
    len_values = len(values)
  File "/usr/local/lib/python3.13/site-packages/django/db/models/query.py", line 382, in __len__
    self._fetch_all()
    ~~~~~~~~~~~~~~~^^
  File "/usr/local/lib/python3.13/site-packages/django/db/models/query.py", line 1928, in _fetch_all
    self._result_cache = list(self._iterable_class(self))
                         ~~~~^^^^^^^^^^^^^^^^^^^^^^^^^^^^
  File "/usr/local/lib/python3.13/site-packages/django/db/models/query.py", line 91, in __iter__
    results = compiler.execute_sql(
        chunked_fetch=self.chunked_fetch, chunk_size=self.chunk_size
    )
  File "/usr/local/lib/python3.13/site-packages/django/db/models/sql/compiler.py", line 1560, in execute_sql
    cursor = self.connection.cursor()
  File "/usr/local/lib/python3.13/site-packages/django/utils/asyncio.py", line 26, in inner
    return func(*args, **kwargs)
  File "/usr/local/lib/python3.13/site-packages/django/db/backends/base/base.py", line 316, in cursor
    return self._cursor()
           ~~~~~~~~~~~~^^
  File "/usr/local/lib/python3.13/site-packages/django/db/backends/base/base.py", line 292, in _cursor
    self.ensure_connection()
    ~~~~~~~~~~~~~~~~~~~~~~^^
  File "/usr/local/lib/python3.13/site-packages/django/utils/asyncio.py", line 26, in inner
    return func(*args, **kwargs)
  File "/usr/local/lib/python3.13/site-packages/django/db/backends/base/base.py", line 274, in ensure_connection
    with self.wrap_database_errors:
         ^^^^^^^^^^^^^^^^^^^^^^^^^
  File "/usr/local/lib/python3.13/site-packages/django/db/utils.py", line 91, in __exit__
    raise dj_exc_value.with_traceback(traceback) from exc_value
  File "/usr/local/lib/python3.13/site-packages/django/db/backends/base/base.py", line 275, in ensure_connection
    self.connect()
    ~~~~~~~~~~~~^^
  File "/usr/local/lib/python3.13/site-packages/django/utils/asyncio.py", line 26, in inner
    return func(*args, **kwargs)
  File "/usr/local/lib/python3.13/site-packages/django/db/backends/base/base.py", line 256, in connect
    self.connection = self.get_new_connection(conn_params)
                      ~~~~~~~~~~~~~~~~~~~~~~~^^^^^^^^^^^^^
  File "/usr/local/lib/python3.13/site-packages/django/utils/asyncio.py", line 26, in inner
    return func(*args, **kwargs)
  File "/usr/local/lib/python3.13/site-packages/django/db/backends/postgresql/base.py", line 277, in get_new_connection
    connection = self.Database.connect(**conn_params)
  File "/usr/local/lib/python3.13/site-packages/psycopg2/__init__.py", line 122, in connect
    conn = _connect(dsn, connection_factory=connection_factory, **kwasync)
django.db.utils.OperationalError: connection to server at "aws-0-us-west-1.pooler.supabase.com" (54.177.55.191), port 5432 failed: FATAL:  Tenant or user not found
connection to server at "aws-0-us-west-1.pooler.supabase.com" (54.177.55.191), port 5432 failed: FATAL:  Tenant or user not found

Internal Server Error: /reservas/cargar_reserva/
Traceback (most recent call last):
  File "/usr/local/lib/python3.13/site-packages/django/db/backends/base/base.py", line 275, in ensure_connection
    self.connect()
    ~~~~~~~~~~~~^^
  File "/usr/local/lib/python3.13/site-packages/django/utils/asyncio.py", line 26, in inner
    return func(*args, **kwargs)
  File "/usr/local/lib/python3.13/site-packages/django/db/backends/base/base.py", line 256, in connect
    self.connection = self.get_new_connection(conn_params)
                      ~~~~~~~~~~~~~~~~~~~~~~~^^^^^^^^^^^^^
  File "/usr/local/lib/python3.13/site-packages/django/utils/asyncio.py", line 26, in inner
    return func(*args, **kwargs)
  File "/usr/local/lib/python3.13/site-packages/django/db/backends/postgresql/base.py", line 277, in get_new_connection
    connection = self.Database.connect(**conn_params)
  File "/usr/local/lib/python3.13/site-packages/psycopg2/__init__.py", line 122, in connect
    conn = _connect(dsn, connection_factory=connection_factory, **kwasync)
psycopg2.OperationalError: connection to server at "aws-0-us-west-1.pooler.supabase.com" (54.177.55.191), port 5432 failed: FATAL:  Tenant or user not found
connection to server at "aws-0-us-west-1.pooler.supabase.com" (54.177.55.191), port 5432 failed: FATAL:  Tenant or user not found


The above exception was the direct cause of the following exception:

Traceback (most recent call last):
  File "/usr/local/lib/python3.13/site-packages/django/core/handlers/exception.py", line 55, in inner
    response = get_response(request)
  File "/usr/local/lib/python3.13/site-packages/django/core/handlers/base.py", line 197, in _get_response
    response = wrapped_callback(request, *callback_args, **callback_kwargs)
  File "/app/reservas/views.py", line 259, in cargar_reserva
    return render(request, "reservas/cargar_reserva.html", {"form": form})
  File "/usr/local/lib/python3.13/site-packages/django/shortcuts.py", line 25, in render
    content = loader.render_to_string(template_name, context, request, using=using)
  File "/usr/local/lib/python3.13/site-packages/django/template/loader.py", line 62, in render_to_string
    return template.render(context, request)
           ~~~~~~~~~~~~~~~^^^^^^^^^^^^^^^^^^
  File "/usr/local/lib/python3.13/site-packages/django/template/backends/django.py", line 61, in render
    return self.template.render(context)
           ~~~~~~~~~~~~~~~~~~~~^^^^^^^^^
  File "/usr/local/lib/python3.13/site-packages/django/template/base.py", line 171, in render
    return self._render(context)
           ~~~~~~~~~~~~^^^^^^^^^
  File "/usr/local/lib/python3.13/site-packages/django/template/base.py", line 163, in _render
    return self.nodelist.render(context)
           ~~~~~~~~~~~~~~~~~~~~^^^^^^^^^
  File "/usr/local/lib/python3.13/site-packages/django/template/base.py", line 1000, in render
    return SafeString("".join([node.render_annotated(context) for node in self]))
                               ~~~~~~~~~~~~~~~~~~~~~^^^^^^^^^
  File "/usr/local/lib/python3.13/site-packages/django/template/base.py", line 961, in render_annotated
    return self.render(context)
           ~~~~~~~~~~~^^^^^^^^^
  File "/usr/local/lib/python3.13/site-packages/django/template/loader_tags.py", line 159, in render
    return compiled_parent._render(context)
           ~~~~~~~~~~~~~~~~~~~~~~~^^^^^^^^^
  File "/usr/local/lib/python3.13/site-packages/django/template/base.py", line 163, in _render
    return self.nodelist.render(context)
           ~~~~~~~~~~~~~~~~~~~~^^^^^^^^^
  File "/usr/local/lib/python3.13/site-packages/django/template/base.py", line 1000, in render
    return SafeString("".join([node.render_annotated(context) for node in self]))
                               ~~~~~~~~~~~~~~~~~~~~~^^^^^^^^^
  File "/usr/local/lib/python3.13/site-packages/django/template/base.py", line 961, in render_annotated
    return self.render(context)
           ~~~~~~~~~~~^^^^^^^^^
  File "/usr/local/lib/python3.13/site-packages/django/template/loader_tags.py", line 65, in render
    result = block.nodelist.render(context)
  File "/usr/local/lib/python3.13/site-packages/django/template/base.py", line 1000, in render
    return SafeString("".join([node.render_annotated(context) for node in self]))
                               ~~~~~~~~~~~~~~~~~~~~~^^^^^^^^^
  File "/usr/local/lib/python3.13/site-packages/django/template/base.py", line 961, in render_annotated
    return self.render(context)
           ~~~~~~~~~~~^^^^^^^^^
  File "/usr/local/lib/python3.13/site-packages/django/template/base.py", line 1059, in render
    output = self.filter_expression.resolve(context)
  File "/usr/local/lib/python3.13/site-packages/django/template/base.py", line 710, in resolve
    obj = self.var.resolve(context)
  File "/usr/local/lib/python3.13/site-packages/django/template/base.py", line 842, in resolve
    value = self._resolve_lookup(context)
  File "/usr/local/lib/python3.13/site-packages/django/template/base.py", line 909, in _resolve_lookup
    current = current()
  File "/usr/local/lib/python3.13/site-packages/django/forms/utils.py", line 87, in as_p
    return self.render(self.template_name_p)
           ~~~~~~~~~~~^^^^^^^^^^^^^^^^^^^^^^
  File "/usr/local/lib/python3.13/site-packages/django/forms/utils.py", line 55, in render
    return mark_safe(renderer.render(template, context))
                     ~~~~~~~~~~~~~~~^^^^^^^^^^^^^^^^^^^
  File "/usr/local/lib/python3.13/site-packages/django/forms/renderers.py", line 29, in render
    return template.render(context, request=request).strip()
           ~~~~~~~~~~~~~~~^^^^^^^^^^^^^^^^^^^^^^^^^^
  File "/usr/local/lib/python3.13/site-packages/django/template/backends/django.py", line 61, in render
    return self.template.render(context)
           ~~~~~~~~~~~~~~~~~~~~^^^^^^^^^
  File "/usr/local/lib/python3.13/site-packages/django/template/base.py", line 171, in render
    return self._render(context)
           ~~~~~~~~~~~~^^^^^^^^^
  File "/usr/local/lib/python3.13/site-packages/django/template/base.py", line 163, in _render
    return self.nodelist.render(context)
           ~~~~~~~~~~~~~~~~~~~~^^^^^^^^^
  File "/usr/local/lib/python3.13/site-packages/django/template/base.py", line 1000, in render
    return SafeString("".join([node.render_annotated(context) for node in self]))
                               ~~~~~~~~~~~~~~~~~~~~~^^^^^^^^^
  File "/usr/local/lib/python3.13/site-packages/django/template/base.py", line 961, in render_annotated
    return self.render(context)
           ~~~~~~~~~~~^^^^^^^^^
  File "/usr/local/lib/python3.13/site-packages/django/template/defaulttags.py", line 242, in render
    nodelist.append(node.render_annotated(context))
                    ~~~~~~~~~~~~~~~~~~~~~^^^^^^^^^
  File "/usr/local/lib/python3.13/site-packages/django/template/base.py", line 961, in render_annotated
    return self.render(context)
           ~~~~~~~~~~~^^^^^^^^^
  File "/usr/local/lib/python3.13/site-packages/django/template/base.py", line 1065, in render
    return render_value_in_context(output, context)
  File "/usr/local/lib/python3.13/site-packages/django/template/base.py", line 1042, in render_value_in_context
    value = str(value)
  File "/usr/local/lib/python3.13/site-packages/django/forms/utils.py", line 79, in __str__
    return self.as_widget()
           ~~~~~~~~~~~~~~^^
  File "/usr/local/lib/python3.13/site-packages/django/forms/boundfield.py", line 108, in as_widget
    return widget.render(
           ~~~~~~~~~~~~~^
        name=self.html_initial_name if only_initial else self.html_name,
        ^^^^^^^^^^^^^^^^^^^^^^^^^^^^^^^^^^^^^^^^^^^^^^^^^^^^^^^^^^^^^^^^
    ...<2 lines>...
        renderer=self.form.renderer,
        ^^^^^^^^^^^^^^^^^^^^^^^^^^^^
    )
    ^
  File "/usr/local/lib/python3.13/site-packages/django/forms/widgets.py", line 278, in render
    context = self.get_context(name, value, attrs)
  File "/usr/local/lib/python3.13/site-packages/django/forms/widgets.py", line 764, in get_context
    context = super().get_context(name, value, attrs)
  File "/usr/local/lib/python3.13/site-packages/django/forms/widgets.py", line 715, in get_context
    context["widget"]["optgroups"] = self.optgroups(
                                     ~~~~~~~~~~~~~~^
        name, context["widget"]["value"], attrs
        ^^^^^^^^^^^^^^^^^^^^^^^^^^^^^^^^^^^^^^^
    )
    ^
  File "/usr/local/lib/python3.13/site-packages/django/forms/widgets.py", line 655, in optgroups
    for index, (option_value, option_label) in enumerate(self.choices):
                                               ~~~~~~~~~^^^^^^^^^^^^^^
  File "/usr/local/lib/python3.13/site-packages/django/forms/models.py", line 1422, in __iter__
    for obj in queryset:
               ^^^^^^^^
  File "/usr/local/lib/python3.13/site-packages/django/db/models/query.py", line 518, in _iterator
    yield from iterable
  File "/usr/local/lib/python3.13/site-packages/django/db/models/query.py", line 91, in __iter__
    results = compiler.execute_sql(
        chunked_fetch=self.chunked_fetch, chunk_size=self.chunk_size
    )
  File "/usr/local/lib/python3.13/site-packages/django/db/models/sql/compiler.py", line 1558, in execute_sql
    cursor = self.connection.chunked_cursor()
  File "/usr/local/lib/python3.13/site-packages/django/utils/asyncio.py", line 26, in inner
    return func(*args, **kwargs)
  File "/usr/local/lib/python3.13/site-packages/django/db/backends/postgresql/base.py", line 365, in chunked_cursor
    return self._cursor(
           ~~~~~~~~~~~~^
        name="_django_curs_%d_%s_%d"
        ^^^^^^^^^^^^^^^^^^^^^^^^^^^^
    ...<5 lines>...
        )
        ^
    )
    ^
  File "/usr/local/lib/python3.13/site-packages/django/db/backends/base/base.py", line 292, in _cursor
    self.ensure_connection()
    ~~~~~~~~~~~~~~~~~~~~~~^^
  File "/usr/local/lib/python3.13/site-packages/django/utils/asyncio.py", line 26, in inner
    return func(*args, **kwargs)
  File "/usr/local/lib/python3.13/site-packages/django/db/backends/base/base.py", line 274, in ensure_connection
    with self.wrap_database_errors:
         ^^^^^^^^^^^^^^^^^^^^^^^^^
  File "/usr/local/lib/python3.13/site-packages/django/db/utils.py", line 91, in __exit__
    raise dj_exc_value.with_traceback(traceback) from exc_value
  File "/usr/local/lib/python3.13/site-packages/django/db/backends/base/base.py", line 275, in ensure_connection
    self.connect()
    ~~~~~~~~~~~~^^
  File "/usr/local/lib/python3.13/site-packages/django/utils/asyncio.py", line 26, in inner
    return func(*args, **kwargs)
  File "/usr/local/lib/python3.13/site-packages/django/db/backends/base/base.py", line 256, in connect
    self.connection = self.get_new_connection(conn_params)
                      ~~~~~~~~~~~~~~~~~~~~~~~^^^^^^^^^^^^^
  File "/usr/local/lib/python3.13/site-packages/django/utils/asyncio.py", line 26, in inner
    return func(*args, **kwargs)
  File "/usr/local/lib/python3.13/site-packages/django/db/backends/postgresql/base.py", line 277, in get_new_connection
    connection = self.Database.connect(**conn_params)
  File "/usr/local/lib/python3.13/site-packages/psycopg2/__init__.py", line 122, in connect
    conn = _connect(dsn, connection_factory=connection_factory, **kwasync)
django.db.utils.OperationalError: connection to server at "aws-0-us-west-1.pooler.supabase.com" (54.177.55.191), port 5432 failed: FATAL:  Tenant or user not found
connection to server at "aws-0-us-west-1.pooler.supabase.com" (54.177.55.191), port 5432 failed: FATAL:  Tenant or user not found

Internal Server Error: /reservas/planing/
Traceback (most recent call last):
  File "/usr/local/lib/python3.13/site-packages/django/db/backends/base/base.py", line 275, in ensure_connection
    self.connect()
    ~~~~~~~~~~~~^^
  File "/usr/local/lib/python3.13/site-packages/django/utils/asyncio.py", line 26, in inner
    return func(*args, **kwargs)
  File "/usr/local/lib/python3.13/site-packages/django/db/backends/base/base.py", line 256, in connect
    self.connection = self.get_new_connection(conn_params)
                      ~~~~~~~~~~~~~~~~~~~~~~~^^^^^^^^^^^^^
  File "/usr/local/lib/python3.13/site-packages/django/utils/asyncio.py", line 26, in inner
    return func(*args, **kwargs)
  File "/usr/local/lib/python3.13/site-packages/django/db/backends/postgresql/base.py", line 277, in get_new_connection
    connection = self.Database.connect(**conn_params)
  File "/usr/local/lib/python3.13/site-packages/psycopg2/__init__.py", line 122, in connect
    conn = _connect(dsn, connection_factory=connection_factory, **kwasync)
psycopg2.OperationalError: connection to server at "aws-0-us-west-1.pooler.supabase.com" (54.177.55.191), port 5432 failed: FATAL:  Tenant or user not found
connection to server at "aws-0-us-west-1.pooler.supabase.com" (54.177.55.191), port 5432 failed: FATAL:  Tenant or user not found


The above exception was the direct cause of the following exception:

Traceback (most recent call last):
  File "/usr/local/lib/python3.13/site-packages/django/core/handlers/exception.py", line 55, in inner
    response = get_response(request)
  File "/usr/local/lib/python3.13/site-packages/django/core/handlers/base.py", line 197, in _get_response
    response = wrapped_callback(request, *callback_args, **callback_kwargs)
  File "/app/reservas/views.py", line 119, in generar_planing
    habitaciones = list(Habitacion.objects.all())
  File "/usr/local/lib/python3.13/site-packages/django/db/models/query.py", line 400, in __iter__
    self._fetch_all()
    ~~~~~~~~~~~~~~~^^
  File "/usr/local/lib/python3.13/site-packages/django/db/models/query.py", line 1928, in _fetch_all
    self._result_cache = list(self._iterable_class(self))
                         ~~~~^^^^^^^^^^^^^^^^^^^^^^^^^^^^
  File "/usr/local/lib/python3.13/site-packages/django/db/models/query.py", line 91, in __iter__
    results = compiler.execute_sql(
        chunked_fetch=self.chunked_fetch, chunk_size=self.chunk_size
    )
  File "/usr/local/lib/python3.13/site-packages/django/db/models/sql/compiler.py", line 1560, in execute_sql
    cursor = self.connection.cursor()
  File "/usr/local/lib/python3.13/site-packages/django/utils/asyncio.py", line 26, in inner
    return func(*args, **kwargs)
  File "/usr/local/lib/python3.13/site-packages/django/db/backends/base/base.py", line 316, in cursor
    return self._cursor()
           ~~~~~~~~~~~~^^
  File "/usr/local/lib/python3.13/site-packages/django/db/backends/base/base.py", line 292, in _cursor
    self.ensure_connection()
    ~~~~~~~~~~~~~~~~~~~~~~^^
  File "/usr/local/lib/python3.13/site-packages/django/utils/asyncio.py", line 26, in inner
    return func(*args, **kwargs)
  File "/usr/local/lib/python3.13/site-packages/django/db/backends/base/base.py", line 274, in ensure_connection
    with self.wrap_database_errors:
         ^^^^^^^^^^^^^^^^^^^^^^^^^
  File "/usr/local/lib/python3.13/site-packages/django/db/utils.py", line 91, in __exit__
    raise dj_exc_value.with_traceback(traceback) from exc_value
  File "/usr/local/lib/python3.13/site-packages/django/db/backends/base/base.py", line 275, in ensure_connection
    self.connect()
    ~~~~~~~~~~~~^^
  File "/usr/local/lib/python3.13/site-packages/django/utils/asyncio.py", line 26, in inner
    return func(*args, **kwargs)
  File "/usr/local/lib/python3.13/site-packages/django/db/backends/base/base.py", line 256, in connect
    self.connection = self.get_new_connection(conn_params)
                      ~~~~~~~~~~~~~~~~~~~~~~~^^^^^^^^^^^^^
  File "/usr/local/lib/python3.13/site-packages/django/utils/asyncio.py", line 26, in inner
    return func(*args, **kwargs)
  File "/usr/local/lib/python3.13/site-packages/django/db/backends/postgresql/base.py", line 277, in get_new_connection
    connection = self.Database.connect(**conn_params)
  File "/usr/local/lib/python3.13/site-packages/psycopg2/__init__.py", line 122, in connect
    conn = _connect(dsn, connection_factory=connection_factory, **kwasync)
django.db.utils.OperationalError: connection to server at "aws-0-us-west-1.pooler.supabase.com" (54.177.55.191), port 5432 failed: FATAL:  Tenant or user not found
connection to server at "aws-0-us-west-1.pooler.supabase.com" (54.177.55.191), port 5432 failed: FATAL:  Tenant or user not found

Internal Server Error: /reservas/listar_reservas/
Traceback (most recent call last):
  File "/usr/local/lib/python3.13/site-packages/django/db/backends/base/base.py", line 275, in ensure_connection
    self.connect()
    ~~~~~~~~~~~~^^
  File "/usr/local/lib/python3.13/site-packages/django/utils/asyncio.py", line 26, in inner
    return func(*args, **kwargs)
  File "/usr/local/lib/python3.13/site-packages/django/db/backends/base/base.py", line 256, in connect
    self.connection = self.get_new_connection(conn_params)
                      ~~~~~~~~~~~~~~~~~~~~~~~^^^^^^^^^^^^^
  File "/usr/local/lib/python3.13/site-packages/django/utils/asyncio.py", line 26, in inner
    return func(*args, **kwargs)
  File "/usr/local/lib/python3.13/site-packages/django/db/backends/postgresql/base.py", line 277, in get_new_connection
    connection = self.Database.connect(**conn_params)
  File "/usr/local/lib/python3.13/site-packages/psycopg2/__init__.py", line 122, in connect
    conn = _connect(dsn, connection_factory=connection_factory, **kwasync)
psycopg2.OperationalError: connection to server at "aws-0-us-west-1.pooler.supabase.com" (54.177.55.191), port 5432 failed: FATAL:  Tenant or user not found
connection to server at "aws-0-us-west-1.pooler.supabase.com" (54.177.55.191), port 5432 failed: FATAL:  Tenant or user not found


The above exception was the direct cause of the following exception:

Traceback (most recent call last):
  File "/usr/local/lib/python3.13/site-packages/django/core/handlers/exception.py", line 55, in inner
    response = get_response(request)
  File "/usr/local/lib/python3.13/site-packages/django/core/handlers/base.py", line 197, in _get_response
    response = wrapped_callback(request, *callback_args, **callback_kwargs)
  File "/app/reservas/views.py", line 465, in listar_reservas
    for reserva in reservas:
                   ^^^^^^^^
  File "/usr/local/lib/python3.13/site-packages/django/db/models/query.py", line 400, in __iter__
    self._fetch_all()
    ~~~~~~~~~~~~~~~^^
  File "/usr/local/lib/python3.13/site-packages/django/db/models/query.py", line 1928, in _fetch_all
    self._result_cache = list(self._iterable_class(self))
                         ~~~~^^^^^^^^^^^^^^^^^^^^^^^^^^^^
  File "/usr/local/lib/python3.13/site-packages/django/db/models/query.py", line 91, in __iter__
    results = compiler.execute_sql(
        chunked_fetch=self.chunked_fetch, chunk_size=self.chunk_size
    )
  File "/usr/local/lib/python3.13/site-packages/django/db/models/sql/compiler.py", line 1560, in execute_sql
    cursor = self.connection.cursor()
  File "/usr/local/lib/python3.13/site-packages/django/utils/asyncio.py", line 26, in inner
    return func(*args, **kwargs)
  File "/usr/local/lib/python3.13/site-packages/django/db/backends/base/base.py", line 316, in cursor
    return self._cursor()
           ~~~~~~~~~~~~^^
  File "/usr/local/lib/python3.13/site-packages/django/db/backends/base/base.py", line 292, in _cursor
    self.ensure_connection()
    ~~~~~~~~~~~~~~~~~~~~~~^^
  File "/usr/local/lib/python3.13/site-packages/django/utils/asyncio.py", line 26, in inner
    return func(*args, **kwargs)
  File "/usr/local/lib/python3.13/site-packages/django/db/backends/base/base.py", line 274, in ensure_connection
    with self.wrap_database_errors:
         ^^^^^^^^^^^^^^^^^^^^^^^^^
  File "/usr/local/lib/python3.13/site-packages/django/db/utils.py", line 91, in __exit__
    raise dj_exc_value.with_traceback(traceback) from exc_value
  File "/usr/local/lib/python3.13/site-packages/django/db/backends/base/base.py", line 275, in ensure_connection
    self.connect()
    ~~~~~~~~~~~~^^
  File "/usr/local/lib/python3.13/site-packages/django/utils/asyncio.py", line 26, in inner
    return func(*args, **kwargs)
  File "/usr/local/lib/python3.13/site-packages/django/db/backends/base/base.py", line 256, in connect
    self.connection = self.get_new_connection(conn_params)
                      ~~~~~~~~~~~~~~~~~~~~~~~^^^^^^^^^^^^^
  File "/usr/local/lib/python3.13/site-packages/django/utils/asyncio.py", line 26, in inner
    return func(*args, **kwargs)
  File "/usr/local/lib/python3.13/site-packages/django/db/backends/postgresql/base.py", line 277, in get_new_connection
    connection = self.Database.connect(**conn_params)
  File "/usr/local/lib/python3.13/site-packages/psycopg2/__init__.py", line 122, in connect
    conn = _connect(dsn, connection_factory=connection_factory, **kwasync)
django.db.utils.OperationalError: connection to server at "aws-0-us-west-1.pooler.supabase.com" (54.177.55.191), port 5432 failed: FATAL:  Tenant or user not found
connection to server at "aws-0-us-west-1.pooler.supabase.com" (54.177.55.191), port 5432 failed: FATAL:  Tenant or user not found

Internal Server Error: /reservas/listar_habitaciones/
Traceback (most recent call last):
  File "/usr/local/lib/python3.13/site-packages/django/db/backends/base/base.py", line 275, in ensure_connection
    self.connect()
    ~~~~~~~~~~~~^^
  File "/usr/local/lib/python3.13/site-packages/django/utils/asyncio.py", line 26, in inner
    return func(*args, **kwargs)
  File "/usr/local/lib/python3.13/site-packages/django/db/backends/base/base.py", line 256, in connect
    self.connection = self.get_new_connection(conn_params)
                      ~~~~~~~~~~~~~~~~~~~~~~~^^^^^^^^^^^^^
  File "/usr/local/lib/python3.13/site-packages/django/utils/asyncio.py", line 26, in inner
    return func(*args, **kwargs)
  File "/usr/local/lib/python3.13/site-packages/django/db/backends/postgresql/base.py", line 277, in get_new_connection
    connection = self.Database.connect(**conn_params)
  File "/usr/local/lib/python3.13/site-packages/psycopg2/__init__.py", line 122, in connect
    conn = _connect(dsn, connection_factory=connection_factory, **kwasync)
psycopg2.OperationalError: connection to server at "aws-0-us-west-1.pooler.supabase.com" (54.177.55.191), port 5432 failed: FATAL:  Tenant or user not found
connection to server at "aws-0-us-west-1.pooler.supabase.com" (54.177.55.191), port 5432 failed: FATAL:  Tenant or user not found


The above exception was the direct cause of the following exception:

Traceback (most recent call last):
  File "/usr/local/lib/python3.13/site-packages/django/core/handlers/exception.py", line 55, in inner
    response = get_response(request)
  File "/usr/local/lib/python3.13/site-packages/django/core/handlers/base.py", line 197, in _get_response
    response = wrapped_callback(request, *callback_args, **callback_kwargs)
  File "/app/reservas/views.py", line 195, in listar_habitaciones
    return render(
        request, "reservas/listar_habitaciones.html", {"habitaciones": habitaciones}
    )
  File "/usr/local/lib/python3.13/site-packages/django/shortcuts.py", line 25, in render
    content = loader.render_to_string(template_name, context, request, using=using)
  File "/usr/local/lib/python3.13/site-packages/django/template/loader.py", line 62, in render_to_string
    return template.render(context, request)
           ~~~~~~~~~~~~~~~^^^^^^^^^^^^^^^^^^
  File "/usr/local/lib/python3.13/site-packages/django/template/backends/django.py", line 61, in render
    return self.template.render(context)
           ~~~~~~~~~~~~~~~~~~~~^^^^^^^^^
  File "/usr/local/lib/python3.13/site-packages/django/template/base.py", line 171, in render
    return self._render(context)
           ~~~~~~~~~~~~^^^^^^^^^
  File "/usr/local/lib/python3.13/site-packages/django/template/base.py", line 163, in _render
    return self.nodelist.render(context)
           ~~~~~~~~~~~~~~~~~~~~^^^^^^^^^
  File "/usr/local/lib/python3.13/site-packages/django/template/base.py", line 1000, in render
    return SafeString("".join([node.render_annotated(context) for node in self]))
                               ~~~~~~~~~~~~~~~~~~~~~^^^^^^^^^
  File "/usr/local/lib/python3.13/site-packages/django/template/base.py", line 961, in render_annotated
    return self.render(context)
           ~~~~~~~~~~~^^^^^^^^^
  File "/usr/local/lib/python3.13/site-packages/django/template/loader_tags.py", line 159, in render
    return compiled_parent._render(context)
           ~~~~~~~~~~~~~~~~~~~~~~~^^^^^^^^^
  File "/usr/local/lib/python3.13/site-packages/django/template/base.py", line 163, in _render
    return self.nodelist.render(context)
           ~~~~~~~~~~~~~~~~~~~~^^^^^^^^^
  File "/usr/local/lib/python3.13/site-packages/django/template/base.py", line 1000, in render
    return SafeString("".join([node.render_annotated(context) for node in self]))
                               ~~~~~~~~~~~~~~~~~~~~~^^^^^^^^^
  File "/usr/local/lib/python3.13/site-packages/django/template/base.py", line 961, in render_annotated
    return self.render(context)
           ~~~~~~~~~~~^^^^^^^^^
  File "/usr/local/lib/python3.13/site-packages/django/template/loader_tags.py", line 65, in render
    result = block.nodelist.render(context)
  File "/usr/local/lib/python3.13/site-packages/django/template/base.py", line 1000, in render
    return SafeString("".join([node.render_annotated(context) for node in self]))
                               ~~~~~~~~~~~~~~~~~~~~~^^^^^^^^^
  File "/usr/local/lib/python3.13/site-packages/django/template/base.py", line 961, in render_annotated
    return self.render(context)
           ~~~~~~~~~~~^^^^^^^^^
  File "/usr/local/lib/python3.13/site-packages/django/template/defaulttags.py", line 198, in render
    len_values = len(values)
  File "/usr/local/lib/python3.13/site-packages/django/db/models/query.py", line 382, in __len__
    self._fetch_all()
    ~~~~~~~~~~~~~~~^^
  File "/usr/local/lib/python3.13/site-packages/django/db/models/query.py", line 1928, in _fetch_all
    self._result_cache = list(self._iterable_class(self))
                         ~~~~^^^^^^^^^^^^^^^^^^^^^^^^^^^^
  File "/usr/local/lib/python3.13/site-packages/django/db/models/query.py", line 91, in __iter__
    results = compiler.execute_sql(
        chunked_fetch=self.chunked_fetch, chunk_size=self.chunk_size
    )
  File "/usr/local/lib/python3.13/site-packages/django/db/models/sql/compiler.py", line 1560, in execute_sql
    cursor = self.connection.cursor()
  File "/usr/local/lib/python3.13/site-packages/django/utils/asyncio.py", line 26, in inner
    return func(*args, **kwargs)
  File "/usr/local/lib/python3.13/site-packages/django/db/backends/base/base.py", line 316, in cursor
    return self._cursor()
           ~~~~~~~~~~~~^^
  File "/usr/local/lib/python3.13/site-packages/django/db/backends/base/base.py", line 292, in _cursor
    self.ensure_connection()
    ~~~~~~~~~~~~~~~~~~~~~~^^
  File "/usr/local/lib/python3.13/site-packages/django/utils/asyncio.py", line 26, in inner
    return func(*args, **kwargs)
  File "/usr/local/lib/python3.13/site-packages/django/db/backends/base/base.py", line 274, in ensure_connection
    with self.wrap_database_errors:
         ^^^^^^^^^^^^^^^^^^^^^^^^^
  File "/usr/local/lib/python3.13/site-packages/django/db/utils.py", line 91, in __exit__
    raise dj_exc_value.with_traceback(traceback) from exc_value
  File "/usr/local/lib/python3.13/site-packages/django/db/backends/base/base.py", line 275, in ensure_connection
    self.connect()
    ~~~~~~~~~~~~^^
  File "/usr/local/lib/python3.13/site-packages/django/utils/asyncio.py", line 26, in inner
    return func(*args, **kwargs)
  File "/usr/local/lib/python3.13/site-packages/django/db/backends/base/base.py", line 256, in connect
    self.connection = self.get_new_connection(conn_params)
                      ~~~~~~~~~~~~~~~~~~~~~~~^^^^^^^^^^^^^
  File "/usr/local/lib/python3.13/site-packages/django/utils/asyncio.py", line 26, in inner
    return func(*args, **kwargs)
  File "/usr/local/lib/python3.13/site-packages/django/db/backends/postgresql/base.py", line 277, in get_new_connection
    connection = self.Database.connect(**conn_params)
  File "/usr/local/lib/python3.13/site-packages/psycopg2/__init__.py", line 122, in connect
    conn = _connect(dsn, connection_factory=connection_factory, **kwasync)
django.db.utils.OperationalError: connection to server at "aws-0-us-west-1.pooler.supabase.com" (54.177.55.191), port 5432 failed: FATAL:  Tenant or user not found
connection to server at "aws-0-us-west-1.pooler.supabase.com" (54.177.55.191), port 5432 failed: FATAL:  Tenant or user not found

Internal Server Error: /reservas/cargar_reserva/
Traceback (most recent call last):
  File "/usr/local/lib/python3.13/site-packages/django/db/backends/base/base.py", line 275, in ensure_connection
    self.connect()
    ~~~~~~~~~~~~^^
  File "/usr/local/lib/python3.13/site-packages/django/utils/asyncio.py", line 26, in inner
    return func(*args, **kwargs)
  File "/usr/local/lib/python3.13/site-packages/django/db/backends/base/base.py", line 256, in connect
    self.connection = self.get_new_connection(conn_params)
                      ~~~~~~~~~~~~~~~~~~~~~~~^^^^^^^^^^^^^
  File "/usr/local/lib/python3.13/site-packages/django/utils/asyncio.py", line 26, in inner
    return func(*args, **kwargs)
  File "/usr/local/lib/python3.13/site-packages/django/db/backends/postgresql/base.py", line 277, in get_new_connection
    connection = self.Database.connect(**conn_params)
  File "/usr/local/lib/python3.13/site-packages/psycopg2/__init__.py", line 122, in connect
    conn = _connect(dsn, connection_factory=connection_factory, **kwasync)
psycopg2.OperationalError: connection to server at "aws-0-us-west-1.pooler.supabase.com" (54.177.55.191), port 5432 failed: FATAL:  Tenant or user not found
connection to server at "aws-0-us-west-1.pooler.supabase.com" (54.177.55.191), port 5432 failed: FATAL:  Tenant or user not found


The above exception was the direct cause of the following exception:

Traceback (most recent call last):
  File "/usr/local/lib/python3.13/site-packages/django/core/handlers/exception.py", line 55, in inner
    response = get_response(request)
  File "/usr/local/lib/python3.13/site-packages/django/core/handlers/base.py", line 197, in _get_response
    response = wrapped_callback(request, *callback_args, **callback_kwargs)
  File "/app/reservas/views.py", line 259, in cargar_reserva
    return render(request, "reservas/cargar_reserva.html", {"form": form})
  File "/usr/local/lib/python3.13/site-packages/django/shortcuts.py", line 25, in render
    content = loader.render_to_string(template_name, context, request, using=using)
  File "/usr/local/lib/python3.13/site-packages/django/template/loader.py", line 62, in render_to_string
    return template.render(context, request)
           ~~~~~~~~~~~~~~~^^^^^^^^^^^^^^^^^^
  File "/usr/local/lib/python3.13/site-packages/django/template/backends/django.py", line 61, in render
    return self.template.render(context)
           ~~~~~~~~~~~~~~~~~~~~^^^^^^^^^
  File "/usr/local/lib/python3.13/site-packages/django/template/base.py", line 171, in render
    return self._render(context)
           ~~~~~~~~~~~~^^^^^^^^^
  File "/usr/local/lib/python3.13/site-packages/django/template/base.py", line 163, in _render
    return self.nodelist.render(context)
           ~~~~~~~~~~~~~~~~~~~~^^^^^^^^^
  File "/usr/local/lib/python3.13/site-packages/django/template/base.py", line 1000, in render
    return SafeString("".join([node.render_annotated(context) for node in self]))
                               ~~~~~~~~~~~~~~~~~~~~~^^^^^^^^^
  File "/usr/local/lib/python3.13/site-packages/django/template/base.py", line 961, in render_annotated
    return self.render(context)
           ~~~~~~~~~~~^^^^^^^^^
  File "/usr/local/lib/python3.13/site-packages/django/template/loader_tags.py", line 159, in render
    return compiled_parent._render(context)
           ~~~~~~~~~~~~~~~~~~~~~~~^^^^^^^^^
  File "/usr/local/lib/python3.13/site-packages/django/template/base.py", line 163, in _render
    return self.nodelist.render(context)
           ~~~~~~~~~~~~~~~~~~~~^^^^^^^^^
  File "/usr/local/lib/python3.13/site-packages/django/template/base.py", line 1000, in render
    return SafeString("".join([node.render_annotated(context) for node in self]))
                               ~~~~~~~~~~~~~~~~~~~~~^^^^^^^^^
  File "/usr/local/lib/python3.13/site-packages/django/template/base.py", line 961, in render_annotated
    return self.render(context)
           ~~~~~~~~~~~^^^^^^^^^
  File "/usr/local/lib/python3.13/site-packages/django/template/loader_tags.py", line 65, in render
    result = block.nodelist.render(context)
  File "/usr/local/lib/python3.13/site-packages/django/template/base.py", line 1000, in render
    return SafeString("".join([node.render_annotated(context) for node in self]))
                               ~~~~~~~~~~~~~~~~~~~~~^^^^^^^^^
  File "/usr/local/lib/python3.13/site-packages/django/template/base.py", line 961, in render_annotated
    return self.render(context)
           ~~~~~~~~~~~^^^^^^^^^
  File "/usr/local/lib/python3.13/site-packages/django/template/base.py", line 1059, in render
    output = self.filter_expression.resolve(context)
  File "/usr/local/lib/python3.13/site-packages/django/template/base.py", line 710, in resolve
    obj = self.var.resolve(context)
  File "/usr/local/lib/python3.13/site-packages/django/template/base.py", line 842, in resolve
    value = self._resolve_lookup(context)
  File "/usr/local/lib/python3.13/site-packages/django/template/base.py", line 909, in _resolve_lookup
    current = current()
  File "/usr/local/lib/python3.13/site-packages/django/forms/utils.py", line 87, in as_p
    return self.render(self.template_name_p)
           ~~~~~~~~~~~^^^^^^^^^^^^^^^^^^^^^^
  File "/usr/local/lib/python3.13/site-packages/django/forms/utils.py", line 55, in render
    return mark_safe(renderer.render(template, context))
                     ~~~~~~~~~~~~~~~^^^^^^^^^^^^^^^^^^^
  File "/usr/local/lib/python3.13/site-packages/django/forms/renderers.py", line 29, in render
    return template.render(context, request=request).strip()
           ~~~~~~~~~~~~~~~^^^^^^^^^^^^^^^^^^^^^^^^^^
  File "/usr/local/lib/python3.13/site-packages/django/template/backends/django.py", line 61, in render
    return self.template.render(context)
           ~~~~~~~~~~~~~~~~~~~~^^^^^^^^^
  File "/usr/local/lib/python3.13/site-packages/django/template/base.py", line 171, in render
    return self._render(context)
           ~~~~~~~~~~~~^^^^^^^^^
  File "/usr/local/lib/python3.13/site-packages/django/template/base.py", line 163, in _render
    return self.nodelist.render(context)
           ~~~~~~~~~~~~~~~~~~~~^^^^^^^^^
  File "/usr/local/lib/python3.13/site-packages/django/template/base.py", line 1000, in render
    return SafeString("".join([node.render_annotated(context) for node in self]))
                               ~~~~~~~~~~~~~~~~~~~~~^^^^^^^^^
  File "/usr/local/lib/python3.13/site-packages/django/template/base.py", line 961, in render_annotated
    return self.render(context)
           ~~~~~~~~~~~^^^^^^^^^
  File "/usr/local/lib/python3.13/site-packages/django/template/defaulttags.py", line 242, in render
    nodelist.append(node.render_annotated(context))
                    ~~~~~~~~~~~~~~~~~~~~~^^^^^^^^^
  File "/usr/local/lib/python3.13/site-packages/django/template/base.py", line 961, in render_annotated
    return self.render(context)
           ~~~~~~~~~~~^^^^^^^^^
  File "/usr/local/lib/python3.13/site-packages/django/template/base.py", line 1065, in render
    return render_value_in_context(output, context)
  File "/usr/local/lib/python3.13/site-packages/django/template/base.py", line 1042, in render_value_in_context
    value = str(value)
  File "/usr/local/lib/python3.13/site-packages/django/forms/utils.py", line 79, in __str__
    return self.as_widget()
           ~~~~~~~~~~~~~~^^
  File "/usr/local/lib/python3.13/site-packages/django/forms/boundfield.py", line 108, in as_widget
    return widget.render(
           ~~~~~~~~~~~~~^
        name=self.html_initial_name if only_initial else self.html_name,
        ^^^^^^^^^^^^^^^^^^^^^^^^^^^^^^^^^^^^^^^^^^^^^^^^^^^^^^^^^^^^^^^^
    ...<2 lines>...
        renderer=self.form.renderer,
        ^^^^^^^^^^^^^^^^^^^^^^^^^^^^
    )
    ^
  File "/usr/local/lib/python3.13/site-packages/django/forms/widgets.py", line 278, in render
    context = self.get_context(name, value, attrs)
  File "/usr/local/lib/python3.13/site-packages/django/forms/widgets.py", line 764, in get_context
    context = super().get_context(name, value, attrs)
  File "/usr/local/lib/python3.13/site-packages/django/forms/widgets.py", line 715, in get_context
    context["widget"]["optgroups"] = self.optgroups(
                                     ~~~~~~~~~~~~~~^
        name, context["widget"]["value"], attrs
        ^^^^^^^^^^^^^^^^^^^^^^^^^^^^^^^^^^^^^^^
    )
    ^
  File "/usr/local/lib/python3.13/site-packages/django/forms/widgets.py", line 655, in optgroups
    for index, (option_value, option_label) in enumerate(self.choices):
                                               ~~~~~~~~~^^^^^^^^^^^^^^
  File "/usr/local/lib/python3.13/site-packages/django/forms/models.py", line 1422, in __iter__
    for obj in queryset:
               ^^^^^^^^
  File "/usr/local/lib/python3.13/site-packages/django/db/models/query.py", line 518, in _iterator
    yield from iterable
  File "/usr/local/lib/python3.13/site-packages/django/db/models/query.py", line 91, in __iter__
    results = compiler.execute_sql(
        chunked_fetch=self.chunked_fetch, chunk_size=self.chunk_size
    )
  File "/usr/local/lib/python3.13/site-packages/django/db/models/sql/compiler.py", line 1558, in execute_sql
    cursor = self.connection.chunked_cursor()
  File "/usr/local/lib/python3.13/site-packages/django/utils/asyncio.py", line 26, in inner
    return func(*args, **kwargs)
  File "/usr/local/lib/python3.13/site-packages/django/db/backends/postgresql/base.py", line 365, in chunked_cursor
    return self._cursor(
           ~~~~~~~~~~~~^
        name="_django_curs_%d_%s_%d"
        ^^^^^^^^^^^^^^^^^^^^^^^^^^^^
    ...<5 lines>...
        )
        ^
    )
    ^
  File "/usr/local/lib/python3.13/site-packages/django/db/backends/base/base.py", line 292, in _cursor
    self.ensure_connection()
    ~~~~~~~~~~~~~~~~~~~~~~^^
  File "/usr/local/lib/python3.13/site-packages/django/utils/asyncio.py", line 26, in inner
    return func(*args, **kwargs)
  File "/usr/local/lib/python3.13/site-packages/django/db/backends/base/base.py", line 274, in ensure_connection
    with self.wrap_database_errors:
         ^^^^^^^^^^^^^^^^^^^^^^^^^
  File "/usr/local/lib/python3.13/site-packages/django/db/utils.py", line 91, in __exit__
    raise dj_exc_value.with_traceback(traceback) from exc_value
  File "/usr/local/lib/python3.13/site-packages/django/db/backends/base/base.py", line 275, in ensure_connection
    self.connect()
    ~~~~~~~~~~~~^^
  File "/usr/local/lib/python3.13/site-packages/django/utils/asyncio.py", line 26, in inner
    return func(*args, **kwargs)
  File "/usr/local/lib/python3.13/site-packages/django/db/backends/base/base.py", line 256, in connect
    self.connection = self.get_new_connection(conn_params)
                      ~~~~~~~~~~~~~~~~~~~~~~~^^^^^^^^^^^^^
  File "/usr/local/lib/python3.13/site-packages/django/utils/asyncio.py", line 26, in inner
    return func(*args, **kwargs)
  File "/usr/local/lib/python3.13/site-packages/django/db/backends/postgresql/base.py", line 277, in get_new_connection
    connection = self.Database.connect(**conn_params)
  File "/usr/local/lib/python3.13/site-packages/psycopg2/__init__.py", line 122, in connect
    conn = _connect(dsn, connection_factory=connection_factory, **kwasync)
django.db.utils.OperationalError: connection to server at "aws-0-us-west-1.pooler.supabase.com" (54.177.55.191), port 5432 failed: FATAL:  Tenant or user not found
connection to server at "aws-0-us-west-1.pooler.supabase.com" (54.177.55.191), port 5432 failed: FATAL:  Tenant or user not found

Internal Server Error: /reservas/cargar_reserva/
Traceback (most recent call last):
  File "/usr/local/lib/python3.13/site-packages/django/db/backends/base/base.py", line 275, in ensure_connection
    self.connect()
    ~~~~~~~~~~~~^^
  File "/usr/local/lib/python3.13/site-packages/django/utils/asyncio.py", line 26, in inner
    return func(*args, **kwargs)
  File "/usr/local/lib/python3.13/site-packages/django/db/backends/base/base.py", line 256, in connect
    self.connection = self.get_new_connection(conn_params)
                      ~~~~~~~~~~~~~~~~~~~~~~~^^^^^^^^^^^^^
  File "/usr/local/lib/python3.13/site-packages/django/utils/asyncio.py", line 26, in inner
    return func(*args, **kwargs)
  File "/usr/local/lib/python3.13/site-packages/django/db/backends/postgresql/base.py", line 277, in get_new_connection
    connection = self.Database.connect(**conn_params)
  File "/usr/local/lib/python3.13/site-packages/psycopg2/__init__.py", line 122, in connect
    conn = _connect(dsn, connection_factory=connection_factory, **kwasync)
psycopg2.OperationalError: connection to server at "aws-0-us-west-1.pooler.supabase.com" (54.177.55.191), port 5432 failed: FATAL:  Tenant or user not found
connection to server at "aws-0-us-west-1.pooler.supabase.com" (54.177.55.191), port 5432 failed: FATAL:  Tenant or user not found


The above exception was the direct cause of the following exception:

Traceback (most recent call last):
  File "/usr/local/lib/python3.13/site-packages/django/core/handlers/exception.py", line 55, in inner
    response = get_response(request)
  File "/usr/local/lib/python3.13/site-packages/django/core/handlers/base.py", line 197, in _get_response
    response = wrapped_callback(request, *callback_args, **callback_kwargs)
  File "/app/reservas/views.py", line 259, in cargar_reserva
    return render(request, "reservas/cargar_reserva.html", {"form": form})
  File "/usr/local/lib/python3.13/site-packages/django/shortcuts.py", line 25, in render
    content = loader.render_to_string(template_name, context, request, using=using)
  File "/usr/local/lib/python3.13/site-packages/django/template/loader.py", line 62, in render_to_string
    return template.render(context, request)
           ~~~~~~~~~~~~~~~^^^^^^^^^^^^^^^^^^
  File "/usr/local/lib/python3.13/site-packages/django/template/backends/django.py", line 61, in render
    return self.template.render(context)
           ~~~~~~~~~~~~~~~~~~~~^^^^^^^^^
  File "/usr/local/lib/python3.13/site-packages/django/template/base.py", line 171, in render
    return self._render(context)
           ~~~~~~~~~~~~^^^^^^^^^
  File "/usr/local/lib/python3.13/site-packages/django/template/base.py", line 163, in _render
    return self.nodelist.render(context)
           ~~~~~~~~~~~~~~~~~~~~^^^^^^^^^
  File "/usr/local/lib/python3.13/site-packages/django/template/base.py", line 1000, in render
    return SafeString("".join([node.render_annotated(context) for node in self]))
                               ~~~~~~~~~~~~~~~~~~~~~^^^^^^^^^
  File "/usr/local/lib/python3.13/site-packages/django/template/base.py", line 961, in render_annotated
    return self.render(context)
           ~~~~~~~~~~~^^^^^^^^^
  File "/usr/local/lib/python3.13/site-packages/django/template/loader_tags.py", line 159, in render
    return compiled_parent._render(context)
           ~~~~~~~~~~~~~~~~~~~~~~~^^^^^^^^^
  File "/usr/local/lib/python3.13/site-packages/django/template/base.py", line 163, in _render
    return self.nodelist.render(context)
           ~~~~~~~~~~~~~~~~~~~~^^^^^^^^^
  File "/usr/local/lib/python3.13/site-packages/django/template/base.py", line 1000, in render
    return SafeString("".join([node.render_annotated(context) for node in self]))
                               ~~~~~~~~~~~~~~~~~~~~~^^^^^^^^^
  File "/usr/local/lib/python3.13/site-packages/django/template/base.py", line 961, in render_annotated
    return self.render(context)
           ~~~~~~~~~~~^^^^^^^^^
  File "/usr/local/lib/python3.13/site-packages/django/template/loader_tags.py", line 65, in render
    result = block.nodelist.render(context)
  File "/usr/local/lib/python3.13/site-packages/django/template/base.py", line 1000, in render
    return SafeString("".join([node.render_annotated(context) for node in self]))
                               ~~~~~~~~~~~~~~~~~~~~~^^^^^^^^^
  File "/usr/local/lib/python3.13/site-packages/django/template/base.py", line 961, in render_annotated
    return self.render(context)
           ~~~~~~~~~~~^^^^^^^^^
  File "/usr/local/lib/python3.13/site-packages/django/template/base.py", line 1059, in render
    output = self.filter_expression.resolve(context)
  File "/usr/local/lib/python3.13/site-packages/django/template/base.py", line 710, in resolve
    obj = self.var.resolve(context)
  File "/usr/local/lib/python3.13/site-packages/django/template/base.py", line 842, in resolve
    value = self._resolve_lookup(context)
  File "/usr/local/lib/python3.13/site-packages/django/template/base.py", line 909, in _resolve_lookup
    current = current()
  File "/usr/local/lib/python3.13/site-packages/django/forms/utils.py", line 87, in as_p
    return self.render(self.template_name_p)
           ~~~~~~~~~~~^^^^^^^^^^^^^^^^^^^^^^
  File "/usr/local/lib/python3.13/site-packages/django/forms/utils.py", line 55, in render
    return mark_safe(renderer.render(template, context))
                     ~~~~~~~~~~~~~~~^^^^^^^^^^^^^^^^^^^
  File "/usr/local/lib/python3.13/site-packages/django/forms/renderers.py", line 29, in render
    return template.render(context, request=request).strip()
           ~~~~~~~~~~~~~~~^^^^^^^^^^^^^^^^^^^^^^^^^^
  File "/usr/local/lib/python3.13/site-packages/django/template/backends/django.py", line 61, in render
    return self.template.render(context)
           ~~~~~~~~~~~~~~~~~~~~^^^^^^^^^
  File "/usr/local/lib/python3.13/site-packages/django/template/base.py", line 171, in render
    return self._render(context)
           ~~~~~~~~~~~~^^^^^^^^^
  File "/usr/local/lib/python3.13/site-packages/django/template/base.py", line 163, in _render
    return self.nodelist.render(context)
           ~~~~~~~~~~~~~~~~~~~~^^^^^^^^^
  File "/usr/local/lib/python3.13/site-packages/django/template/base.py", line 1000, in render
    return SafeString("".join([node.render_annotated(context) for node in self]))
                               ~~~~~~~~~~~~~~~~~~~~~^^^^^^^^^
  File "/usr/local/lib/python3.13/site-packages/django/template/base.py", line 961, in render_annotated
    return self.render(context)
           ~~~~~~~~~~~^^^^^^^^^
  File "/usr/local/lib/python3.13/site-packages/django/template/defaulttags.py", line 242, in render
    nodelist.append(node.render_annotated(context))
                    ~~~~~~~~~~~~~~~~~~~~~^^^^^^^^^
  File "/usr/local/lib/python3.13/site-packages/django/template/base.py", line 961, in render_annotated
    return self.render(context)
           ~~~~~~~~~~~^^^^^^^^^
  File "/usr/local/lib/python3.13/site-packages/django/template/base.py", line 1065, in render
    return render_value_in_context(output, context)
  File "/usr/local/lib/python3.13/site-packages/django/template/base.py", line 1042, in render_value_in_context
    value = str(value)
  File "/usr/local/lib/python3.13/site-packages/django/forms/utils.py", line 79, in __str__
    return self.as_widget()
           ~~~~~~~~~~~~~~^^
  File "/usr/local/lib/python3.13/site-packages/django/forms/boundfield.py", line 108, in as_widget
    return widget.render(
           ~~~~~~~~~~~~~^
        name=self.html_initial_name if only_initial else self.html_name,
        ^^^^^^^^^^^^^^^^^^^^^^^^^^^^^^^^^^^^^^^^^^^^^^^^^^^^^^^^^^^^^^^^
    ...<2 lines>...
        renderer=self.form.renderer,
        ^^^^^^^^^^^^^^^^^^^^^^^^^^^^
    )
    ^
  File "/usr/local/lib/python3.13/site-packages/django/forms/widgets.py", line 278, in render
    context = self.get_context(name, value, attrs)
  File "/usr/local/lib/python3.13/site-packages/django/forms/widgets.py", line 764, in get_context
    context = super().get_context(name, value, attrs)
  File "/usr/local/lib/python3.13/site-packages/django/forms/widgets.py", line 715, in get_context
    context["widget"]["optgroups"] = self.optgroups(
                                     ~~~~~~~~~~~~~~^
        name, context["widget"]["value"], attrs
        ^^^^^^^^^^^^^^^^^^^^^^^^^^^^^^^^^^^^^^^
    )
    ^
  File "/usr/local/lib/python3.13/site-packages/django/forms/widgets.py", line 655, in optgroups
    for index, (option_value, option_label) in enumerate(self.choices):
                                               ~~~~~~~~~^^^^^^^^^^^^^^
  File "/usr/local/lib/python3.13/site-packages/django/forms/models.py", line 1422, in __iter__
    for obj in queryset:
               ^^^^^^^^
  File "/usr/local/lib/python3.13/site-packages/django/db/models/query.py", line 518, in _iterator
    yield from iterable
  File "/usr/local/lib/python3.13/site-packages/django/db/models/query.py", line 91, in __iter__
    results = compiler.execute_sql(
        chunked_fetch=self.chunked_fetch, chunk_size=self.chunk_size
    )
  File "/usr/local/lib/python3.13/site-packages/django/db/models/sql/compiler.py", line 1558, in execute_sql
    cursor = self.connection.chunked_cursor()
  File "/usr/local/lib/python3.13/site-packages/django/utils/asyncio.py", line 26, in inner
    return func(*args, **kwargs)
  File "/usr/local/lib/python3.13/site-packages/django/db/backends/postgresql/base.py", line 365, in chunked_cursor
    return self._cursor(
           ~~~~~~~~~~~~^
        name="_django_curs_%d_%s_%d"
        ^^^^^^^^^^^^^^^^^^^^^^^^^^^^
    ...<5 lines>...
        )
        ^
    )
    ^
  File "/usr/local/lib/python3.13/site-packages/django/db/backends/base/base.py", line 292, in _cursor
    self.ensure_connection()
    ~~~~~~~~~~~~~~~~~~~~~~^^
  File "/usr/local/lib/python3.13/site-packages/django/utils/asyncio.py", line 26, in inner
    return func(*args, **kwargs)
  File "/usr/local/lib/python3.13/site-packages/django/db/backends/base/base.py", line 274, in ensure_connection
    with self.wrap_database_errors:
         ^^^^^^^^^^^^^^^^^^^^^^^^^
  File "/usr/local/lib/python3.13/site-packages/django/db/utils.py", line 91, in __exit__
    raise dj_exc_value.with_traceback(traceback) from exc_value
  File "/usr/local/lib/python3.13/site-packages/django/db/backends/base/base.py", line 275, in ensure_connection
    self.connect()
    ~~~~~~~~~~~~^^
  File "/usr/local/lib/python3.13/site-packages/django/utils/asyncio.py", line 26, in inner
    return func(*args, **kwargs)
  File "/usr/local/lib/python3.13/site-packages/django/db/backends/base/base.py", line 256, in connect
    self.connection = self.get_new_connection(conn_params)
                      ~~~~~~~~~~~~~~~~~~~~~~~^^^^^^^^^^^^^
  File "/usr/local/lib/python3.13/site-packages/django/utils/asyncio.py", line 26, in inner
    return func(*args, **kwargs)
  File "/usr/local/lib/python3.13/site-packages/django/db/backends/postgresql/base.py", line 277, in get_new_connection
    connection = self.Database.connect(**conn_params)
  File "/usr/local/lib/python3.13/site-packages/psycopg2/__init__.py", line 122, in connect
    conn = _connect(dsn, connection_factory=connection_factory, **kwasync)
django.db.utils.OperationalError: connection to server at "aws-0-us-west-1.pooler.supabase.com" (54.177.55.191), port 5432 failed: FATAL:  Tenant or user not found
connection to server at "aws-0-us-west-1.pooler.supabase.com" (54.177.55.191), port 5432 failed: FATAL:  Tenant or user not found

Internal Server Error: /reservas/cargar_reserva/
Traceback (most recent call last):
  File "/usr/local/lib/python3.13/site-packages/django/db/backends/base/base.py", line 275, in ensure_connection
    self.connect()
    ~~~~~~~~~~~~^^
  File "/usr/local/lib/python3.13/site-packages/django/utils/asyncio.py", line 26, in inner
    return func(*args, **kwargs)
  File "/usr/local/lib/python3.13/site-packages/django/db/backends/base/base.py", line 256, in connect
    self.connection = self.get_new_connection(conn_params)
                      ~~~~~~~~~~~~~~~~~~~~~~~^^^^^^^^^^^^^
  File "/usr/local/lib/python3.13/site-packages/django/utils/asyncio.py", line 26, in inner
    return func(*args, **kwargs)
  File "/usr/local/lib/python3.13/site-packages/django/db/backends/postgresql/base.py", line 277, in get_new_connection
    connection = self.Database.connect(**conn_params)
  File "/usr/local/lib/python3.13/site-packages/psycopg2/__init__.py", line 122, in connect
    conn = _connect(dsn, connection_factory=connection_factory, **kwasync)
psycopg2.OperationalError: connection to server at "aws-0-us-west-1.pooler.supabase.com" (52.8.172.168), port 5432 failed: FATAL:  Tenant or user not found
connection to server at "aws-0-us-west-1.pooler.supabase.com" (52.8.172.168), port 5432 failed: FATAL:  Tenant or user not found


The above exception was the direct cause of the following exception:

Traceback (most recent call last):
  File "/usr/local/lib/python3.13/site-packages/django/core/handlers/exception.py", line 55, in inner
    response = get_response(request)
  File "/usr/local/lib/python3.13/site-packages/django/core/handlers/base.py", line 197, in _get_response
    response = wrapped_callback(request, *callback_args, **callback_kwargs)
  File "/app/reservas/views.py", line 259, in cargar_reserva
    return render(request, "reservas/cargar_reserva.html", {"form": form})
  File "/usr/local/lib/python3.13/site-packages/django/shortcuts.py", line 25, in render
    content = loader.render_to_string(template_name, context, request, using=using)
  File "/usr/local/lib/python3.13/site-packages/django/template/loader.py", line 62, in render_to_string
    return template.render(context, request)
           ~~~~~~~~~~~~~~~^^^^^^^^^^^^^^^^^^
  File "/usr/local/lib/python3.13/site-packages/django/template/backends/django.py", line 61, in render
    return self.template.render(context)
           ~~~~~~~~~~~~~~~~~~~~^^^^^^^^^
  File "/usr/local/lib/python3.13/site-packages/django/template/base.py", line 171, in render
    return self._render(context)
           ~~~~~~~~~~~~^^^^^^^^^
  File "/usr/local/lib/python3.13/site-packages/django/template/base.py", line 163, in _render
    return self.nodelist.render(context)
           ~~~~~~~~~~~~~~~~~~~~^^^^^^^^^
  File "/usr/local/lib/python3.13/site-packages/django/template/base.py", line 1000, in render
    return SafeString("".join([node.render_annotated(context) for node in self]))
                               ~~~~~~~~~~~~~~~~~~~~~^^^^^^^^^
  File "/usr/local/lib/python3.13/site-packages/django/template/base.py", line 961, in render_annotated
    return self.render(context)
           ~~~~~~~~~~~^^^^^^^^^
  File "/usr/local/lib/python3.13/site-packages/django/template/loader_tags.py", line 159, in render
    return compiled_parent._render(context)
           ~~~~~~~~~~~~~~~~~~~~~~~^^^^^^^^^
  File "/usr/local/lib/python3.13/site-packages/django/template/base.py", line 163, in _render
    return self.nodelist.render(context)
           ~~~~~~~~~~~~~~~~~~~~^^^^^^^^^
  File "/usr/local/lib/python3.13/site-packages/django/template/base.py", line 1000, in render
    return SafeString("".join([node.render_annotated(context) for node in self]))
                               ~~~~~~~~~~~~~~~~~~~~~^^^^^^^^^
  File "/usr/local/lib/python3.13/site-packages/django/template/base.py", line 961, in render_annotated
    return self.render(context)
           ~~~~~~~~~~~^^^^^^^^^
  File "/usr/local/lib/python3.13/site-packages/django/template/loader_tags.py", line 65, in render
    result = block.nodelist.render(context)
  File "/usr/local/lib/python3.13/site-packages/django/template/base.py", line 1000, in render
    return SafeString("".join([node.render_annotated(context) for node in self]))
                               ~~~~~~~~~~~~~~~~~~~~~^^^^^^^^^
  File "/usr/local/lib/python3.13/site-packages/django/template/base.py", line 961, in render_annotated
    return self.render(context)
           ~~~~~~~~~~~^^^^^^^^^
  File "/usr/local/lib/python3.13/site-packages/django/template/base.py", line 1059, in render
    output = self.filter_expression.resolve(context)
  File "/usr/local/lib/python3.13/site-packages/django/template/base.py", line 710, in resolve
    obj = self.var.resolve(context)
  File "/usr/local/lib/python3.13/site-packages/django/template/base.py", line 842, in resolve
    value = self._resolve_lookup(context)
  File "/usr/local/lib/python3.13/site-packages/django/template/base.py", line 909, in _resolve_lookup
    current = current()
  File "/usr/local/lib/python3.13/site-packages/django/forms/utils.py", line 87, in as_p
    return self.render(self.template_name_p)
           ~~~~~~~~~~~^^^^^^^^^^^^^^^^^^^^^^
  File "/usr/local/lib/python3.13/site-packages/django/forms/utils.py", line 55, in render
    return mark_safe(renderer.render(template, context))
                     ~~~~~~~~~~~~~~~^^^^^^^^^^^^^^^^^^^
  File "/usr/local/lib/python3.13/site-packages/django/forms/renderers.py", line 29, in render
    return template.render(context, request=request).strip()
           ~~~~~~~~~~~~~~~^^^^^^^^^^^^^^^^^^^^^^^^^^
  File "/usr/local/lib/python3.13/site-packages/django/template/backends/django.py", line 61, in render
    return self.template.render(context)
           ~~~~~~~~~~~~~~~~~~~~^^^^^^^^^
  File "/usr/local/lib/python3.13/site-packages/django/template/base.py", line 171, in render
    return self._render(context)
           ~~~~~~~~~~~~^^^^^^^^^
  File "/usr/local/lib/python3.13/site-packages/django/template/base.py", line 163, in _render
    return self.nodelist.render(context)
           ~~~~~~~~~~~~~~~~~~~~^^^^^^^^^
  File "/usr/local/lib/python3.13/site-packages/django/template/base.py", line 1000, in render
    return SafeString("".join([node.render_annotated(context) for node in self]))
                               ~~~~~~~~~~~~~~~~~~~~~^^^^^^^^^
  File "/usr/local/lib/python3.13/site-packages/django/template/base.py", line 961, in render_annotated
    return self.render(context)
           ~~~~~~~~~~~^^^^^^^^^
  File "/usr/local/lib/python3.13/site-packages/django/template/defaulttags.py", line 242, in render
    nodelist.append(node.render_annotated(context))
                    ~~~~~~~~~~~~~~~~~~~~~^^^^^^^^^
  File "/usr/local/lib/python3.13/site-packages/django/template/base.py", line 961, in render_annotated
    return self.render(context)
           ~~~~~~~~~~~^^^^^^^^^
  File "/usr/local/lib/python3.13/site-packages/django/template/base.py", line 1065, in render
    return render_value_in_context(output, context)
  File "/usr/local/lib/python3.13/site-packages/django/template/base.py", line 1042, in render_value_in_context
    value = str(value)
  File "/usr/local/lib/python3.13/site-packages/django/forms/utils.py", line 79, in __str__
    return self.as_widget()
           ~~~~~~~~~~~~~~^^
  File "/usr/local/lib/python3.13/site-packages/django/forms/boundfield.py", line 108, in as_widget
    return widget.render(
           ~~~~~~~~~~~~~^
        name=self.html_initial_name if only_initial else self.html_name,
        ^^^^^^^^^^^^^^^^^^^^^^^^^^^^^^^^^^^^^^^^^^^^^^^^^^^^^^^^^^^^^^^^
    ...<2 lines>...
        renderer=self.form.renderer,
        ^^^^^^^^^^^^^^^^^^^^^^^^^^^^
    )
    ^
  File "/usr/local/lib/python3.13/site-packages/django/forms/widgets.py", line 278, in render
    context = self.get_context(name, value, attrs)
  File "/usr/local/lib/python3.13/site-packages/django/forms/widgets.py", line 764, in get_context
    context = super().get_context(name, value, attrs)
  File "/usr/local/lib/python3.13/site-packages/django/forms/widgets.py", line 715, in get_context
    context["widget"]["optgroups"] = self.optgroups(
                                     ~~~~~~~~~~~~~~^
        name, context["widget"]["value"], attrs
        ^^^^^^^^^^^^^^^^^^^^^^^^^^^^^^^^^^^^^^^
    )
    ^
  File "/usr/local/lib/python3.13/site-packages/django/forms/widgets.py", line 655, in optgroups
    for index, (option_value, option_label) in enumerate(self.choices):
                                               ~~~~~~~~~^^^^^^^^^^^^^^
  File "/usr/local/lib/python3.13/site-packages/django/forms/models.py", line 1422, in __iter__
    for obj in queryset:
               ^^^^^^^^
  File "/usr/local/lib/python3.13/site-packages/django/db/models/query.py", line 518, in _iterator
    yield from iterable
  File "/usr/local/lib/python3.13/site-packages/django/db/models/query.py", line 91, in __iter__
    results = compiler.execute_sql(
        chunked_fetch=self.chunked_fetch, chunk_size=self.chunk_size
    )
  File "/usr/local/lib/python3.13/site-packages/django/db/models/sql/compiler.py", line 1558, in execute_sql
    cursor = self.connection.chunked_cursor()
  File "/usr/local/lib/python3.13/site-packages/django/utils/asyncio.py", line 26, in inner
    return func(*args, **kwargs)
  File "/usr/local/lib/python3.13/site-packages/django/db/backends/postgresql/base.py", line 365, in chunked_cursor
    return self._cursor(
           ~~~~~~~~~~~~^
        name="_django_curs_%d_%s_%d"
        ^^^^^^^^^^^^^^^^^^^^^^^^^^^^
    ...<5 lines>...
        )
        ^
    )
    ^
  File "/usr/local/lib/python3.13/site-packages/django/db/backends/base/base.py", line 292, in _cursor
    self.ensure_connection()
    ~~~~~~~~~~~~~~~~~~~~~~^^
  File "/usr/local/lib/python3.13/site-packages/django/utils/asyncio.py", line 26, in inner
    return func(*args, **kwargs)
  File "/usr/local/lib/python3.13/site-packages/django/db/backends/base/base.py", line 274, in ensure_connection
    with self.wrap_database_errors:
         ^^^^^^^^^^^^^^^^^^^^^^^^^
  File "/usr/local/lib/python3.13/site-packages/django/db/utils.py", line 91, in __exit__
    raise dj_exc_value.with_traceback(traceback) from exc_value
  File "/usr/local/lib/python3.13/site-packages/django/db/backends/base/base.py", line 275, in ensure_connection
    self.connect()
    ~~~~~~~~~~~~^^
  File "/usr/local/lib/python3.13/site-packages/django/utils/asyncio.py", line 26, in inner
    return func(*args, **kwargs)
  File "/usr/local/lib/python3.13/site-packages/django/db/backends/base/base.py", line 256, in connect
    self.connection = self.get_new_connection(conn_params)
                      ~~~~~~~~~~~~~~~~~~~~~~~^^^^^^^^^^^^^
  File "/usr/local/lib/python3.13/site-packages/django/utils/asyncio.py", line 26, in inner
    return func(*args, **kwargs)
  File "/usr/local/lib/python3.13/site-packages/django/db/backends/postgresql/base.py", line 277, in get_new_connection
    connection = self.Database.connect(**conn_params)
  File "/usr/local/lib/python3.13/site-packages/psycopg2/__init__.py", line 122, in connect
    conn = _connect(dsn, connection_factory=connection_factory, **kwasync)
django.db.utils.OperationalError: connection to server at "aws-0-us-west-1.pooler.supabase.com" (52.8.172.168), port 5432 failed: FATAL:  Tenant or user not found
connection to server at "aws-0-us-west-1.pooler.supabase.com" (52.8.172.168), port 5432 failed: FATAL:  Tenant or user not found

Internal Server Error: /reservas/cargar_reserva/
Traceback (most recent call last):
  File "/usr/local/lib/python3.13/site-packages/django/db/backends/base/base.py", line 275, in ensure_connection
    self.connect()
    ~~~~~~~~~~~~^^
  File "/usr/local/lib/python3.13/site-packages/django/utils/asyncio.py", line 26, in inner
    return func(*args, **kwargs)
  File "/usr/local/lib/python3.13/site-packages/django/db/backends/base/base.py", line 256, in connect
    self.connection = self.get_new_connection(conn_params)
                      ~~~~~~~~~~~~~~~~~~~~~~~^^^^^^^^^^^^^
  File "/usr/local/lib/python3.13/site-packages/django/utils/asyncio.py", line 26, in inner
    return func(*args, **kwargs)
  File "/usr/local/lib/python3.13/site-packages/django/db/backends/postgresql/base.py", line 277, in get_new_connection
    connection = self.Database.connect(**conn_params)
  File "/usr/local/lib/python3.13/site-packages/psycopg2/__init__.py", line 122, in connect
    conn = _connect(dsn, connection_factory=connection_factory, **kwasync)
psycopg2.OperationalError: connection to server at "aws-0-us-west-1.pooler.supabase.com" (52.8.172.168), port 5432 failed: FATAL:  Tenant or user not found
connection to server at "aws-0-us-west-1.pooler.supabase.com" (52.8.172.168), port 5432 failed: FATAL:  Tenant or user not found


The above exception was the direct cause of the following exception:

Traceback (most recent call last):
  File "/usr/local/lib/python3.13/site-packages/django/core/handlers/exception.py", line 55, in inner
    response = get_response(request)
  File "/usr/local/lib/python3.13/site-packages/django/core/handlers/base.py", line 197, in _get_response
    response = wrapped_callback(request, *callback_args, **callback_kwargs)
  File "/app/reservas/views.py", line 259, in cargar_reserva
    return render(request, "reservas/cargar_reserva.html", {"form": form})
  File "/usr/local/lib/python3.13/site-packages/django/shortcuts.py", line 25, in render
    content = loader.render_to_string(template_name, context, request, using=using)
  File "/usr/local/lib/python3.13/site-packages/django/template/loader.py", line 62, in render_to_string
    return template.render(context, request)
           ~~~~~~~~~~~~~~~^^^^^^^^^^^^^^^^^^
  File "/usr/local/lib/python3.13/site-packages/django/template/backends/django.py", line 61, in render
    return self.template.render(context)
           ~~~~~~~~~~~~~~~~~~~~^^^^^^^^^
  File "/usr/local/lib/python3.13/site-packages/django/template/base.py", line 171, in render
    return self._render(context)
           ~~~~~~~~~~~~^^^^^^^^^
  File "/usr/local/lib/python3.13/site-packages/django/template/base.py", line 163, in _render
    return self.nodelist.render(context)
           ~~~~~~~~~~~~~~~~~~~~^^^^^^^^^
  File "/usr/local/lib/python3.13/site-packages/django/template/base.py", line 1000, in render
    return SafeString("".join([node.render_annotated(context) for node in self]))
                               ~~~~~~~~~~~~~~~~~~~~~^^^^^^^^^
  File "/usr/local/lib/python3.13/site-packages/django/template/base.py", line 961, in render_annotated
    return self.render(context)
           ~~~~~~~~~~~^^^^^^^^^
  File "/usr/local/lib/python3.13/site-packages/django/template/loader_tags.py", line 159, in render
    return compiled_parent._render(context)
           ~~~~~~~~~~~~~~~~~~~~~~~^^^^^^^^^
  File "/usr/local/lib/python3.13/site-packages/django/template/base.py", line 163, in _render
    return self.nodelist.render(context)
           ~~~~~~~~~~~~~~~~~~~~^^^^^^^^^
  File "/usr/local/lib/python3.13/site-packages/django/template/base.py", line 1000, in render
    return SafeString("".join([node.render_annotated(context) for node in self]))
                               ~~~~~~~~~~~~~~~~~~~~~^^^^^^^^^
  File "/usr/local/lib/python3.13/site-packages/django/template/base.py", line 961, in render_annotated
    return self.render(context)
           ~~~~~~~~~~~^^^^^^^^^
  File "/usr/local/lib/python3.13/site-packages/django/template/loader_tags.py", line 65, in render
    result = block.nodelist.render(context)
  File "/usr/local/lib/python3.13/site-packages/django/template/base.py", line 1000, in render
    return SafeString("".join([node.render_annotated(context) for node in self]))
                               ~~~~~~~~~~~~~~~~~~~~~^^^^^^^^^
  File "/usr/local/lib/python3.13/site-packages/django/template/base.py", line 961, in render_annotated
    return self.render(context)
           ~~~~~~~~~~~^^^^^^^^^
  File "/usr/local/lib/python3.13/site-packages/django/template/base.py", line 1059, in render
    output = self.filter_expression.resolve(context)
  File "/usr/local/lib/python3.13/site-packages/django/template/base.py", line 710, in resolve
    obj = self.var.resolve(context)
  File "/usr/local/lib/python3.13/site-packages/django/template/base.py", line 842, in resolve
    value = self._resolve_lookup(context)
  File "/usr/local/lib/python3.13/site-packages/django/template/base.py", line 909, in _resolve_lookup
    current = current()
  File "/usr/local/lib/python3.13/site-packages/django/forms/utils.py", line 87, in as_p
    return self.render(self.template_name_p)
           ~~~~~~~~~~~^^^^^^^^^^^^^^^^^^^^^^
  File "/usr/local/lib/python3.13/site-packages/django/forms/utils.py", line 55, in render
    return mark_safe(renderer.render(template, context))
                     ~~~~~~~~~~~~~~~^^^^^^^^^^^^^^^^^^^
  File "/usr/local/lib/python3.13/site-packages/django/forms/renderers.py", line 29, in render
    return template.render(context, request=request).strip()
           ~~~~~~~~~~~~~~~^^^^^^^^^^^^^^^^^^^^^^^^^^
  File "/usr/local/lib/python3.13/site-packages/django/template/backends/django.py", line 61, in render
    return self.template.render(context)
           ~~~~~~~~~~~~~~~~~~~~^^^^^^^^^
  File "/usr/local/lib/python3.13/site-packages/django/template/base.py", line 171, in render
    return self._render(context)
           ~~~~~~~~~~~~^^^^^^^^^
  File "/usr/local/lib/python3.13/site-packages/django/template/base.py", line 163, in _render
    return self.nodelist.render(context)
           ~~~~~~~~~~~~~~~~~~~~^^^^^^^^^
  File "/usr/local/lib/python3.13/site-packages/django/template/base.py", line 1000, in render
    return SafeString("".join([node.render_annotated(context) for node in self]))
                               ~~~~~~~~~~~~~~~~~~~~~^^^^^^^^^
  File "/usr/local/lib/python3.13/site-packages/django/template/base.py", line 961, in render_annotated
    return self.render(context)
           ~~~~~~~~~~~^^^^^^^^^
  File "/usr/local/lib/python3.13/site-packages/django/template/defaulttags.py", line 242, in render
    nodelist.append(node.render_annotated(context))
                    ~~~~~~~~~~~~~~~~~~~~~^^^^^^^^^
  File "/usr/local/lib/python3.13/site-packages/django/template/base.py", line 961, in render_annotated
    return self.render(context)
           ~~~~~~~~~~~^^^^^^^^^
  File "/usr/local/lib/python3.13/site-packages/django/template/base.py", line 1065, in render
    return render_value_in_context(output, context)
  File "/usr/local/lib/python3.13/site-packages/django/template/base.py", line 1042, in render_value_in_context
    value = str(value)
  File "/usr/local/lib/python3.13/site-packages/django/forms/utils.py", line 79, in __str__
    return self.as_widget()
           ~~~~~~~~~~~~~~^^
  File "/usr/local/lib/python3.13/site-packages/django/forms/boundfield.py", line 108, in as_widget
    return widget.render(
           ~~~~~~~~~~~~~^
        name=self.html_initial_name if only_initial else self.html_name,
        ^^^^^^^^^^^^^^^^^^^^^^^^^^^^^^^^^^^^^^^^^^^^^^^^^^^^^^^^^^^^^^^^
    ...<2 lines>...
        renderer=self.form.renderer,
        ^^^^^^^^^^^^^^^^^^^^^^^^^^^^
    )
    ^
  File "/usr/local/lib/python3.13/site-packages/django/forms/widgets.py", line 278, in render
    context = self.get_context(name, value, attrs)
  File "/usr/local/lib/python3.13/site-packages/django/forms/widgets.py", line 764, in get_context
    context = super().get_context(name, value, attrs)
  File "/usr/local/lib/python3.13/site-packages/django/forms/widgets.py", line 715, in get_context
    context["widget"]["optgroups"] = self.optgroups(
                                     ~~~~~~~~~~~~~~^
        name, context["widget"]["value"], attrs
        ^^^^^^^^^^^^^^^^^^^^^^^^^^^^^^^^^^^^^^^
    )
    ^
  File "/usr/local/lib/python3.13/site-packages/django/forms/widgets.py", line 655, in optgroups
    for index, (option_value, option_label) in enumerate(self.choices):
                                               ~~~~~~~~~^^^^^^^^^^^^^^
  File "/usr/local/lib/python3.13/site-packages/django/forms/models.py", line 1422, in __iter__
    for obj in queryset:
               ^^^^^^^^
  File "/usr/local/lib/python3.13/site-packages/django/db/models/query.py", line 518, in _iterator
    yield from iterable
  File "/usr/local/lib/python3.13/site-packages/django/db/models/query.py", line 91, in __iter__
    results = compiler.execute_sql(
        chunked_fetch=self.chunked_fetch, chunk_size=self.chunk_size
    )
  File "/usr/local/lib/python3.13/site-packages/django/db/models/sql/compiler.py", line 1558, in execute_sql
    cursor = self.connection.chunked_cursor()
  File "/usr/local/lib/python3.13/site-packages/django/utils/asyncio.py", line 26, in inner
    return func(*args, **kwargs)
  File "/usr/local/lib/python3.13/site-packages/django/db/backends/postgresql/base.py", line 365, in chunked_cursor
    return self._cursor(
           ~~~~~~~~~~~~^
        name="_django_curs_%d_%s_%d"
        ^^^^^^^^^^^^^^^^^^^^^^^^^^^^
    ...<5 lines>...
        )
        ^
    )
    ^
  File "/usr/local/lib/python3.13/site-packages/django/db/backends/base/base.py", line 292, in _cursor
    self.ensure_connection()
    ~~~~~~~~~~~~~~~~~~~~~~^^
  File "/usr/local/lib/python3.13/site-packages/django/utils/asyncio.py", line 26, in inner
    return func(*args, **kwargs)
  File "/usr/local/lib/python3.13/site-packages/django/db/backends/base/base.py", line 274, in ensure_connection
    with self.wrap_database_errors:
         ^^^^^^^^^^^^^^^^^^^^^^^^^
  File "/usr/local/lib/python3.13/site-packages/django/db/utils.py", line 91, in __exit__
    raise dj_exc_value.with_traceback(traceback) from exc_value
  File "/usr/local/lib/python3.13/site-packages/django/db/backends/base/base.py", line 275, in ensure_connection
    self.connect()
    ~~~~~~~~~~~~^^
  File "/usr/local/lib/python3.13/site-packages/django/utils/asyncio.py", line 26, in inner
    return func(*args, **kwargs)
  File "/usr/local/lib/python3.13/site-packages/django/db/backends/base/base.py", line 256, in connect
    self.connection = self.get_new_connection(conn_params)
                      ~~~~~~~~~~~~~~~~~~~~~~~^^^^^^^^^^^^^
  File "/usr/local/lib/python3.13/site-packages/django/utils/asyncio.py", line 26, in inner
    return func(*args, **kwargs)
  File "/usr/local/lib/python3.13/site-packages/django/db/backends/postgresql/base.py", line 277, in get_new_connection
    connection = self.Database.connect(**conn_params)
  File "/usr/local/lib/python3.13/site-packages/psycopg2/__init__.py", line 122, in connect
    conn = _connect(dsn, connection_factory=connection_factory, **kwasync)
django.db.utils.OperationalError: connection to server at "aws-0-us-west-1.pooler.supabase.com" (52.8.172.168), port 5432 failed: FATAL:  Tenant or user not found
connection to server at "aws-0-us-west-1.pooler.supabase.com" (52.8.172.168), port 5432 failed: FATAL:  Tenant or user not found

